Workbook

Sheet Site Data
A1: Site | C1: 45305 | D1: =C1+7 -> 45312 | E1: =D1+7 -> 45319 | F1: =E1+7 -> 45326 | G1: =F1+7 -> 45333 | H1: =G1+7 -> 45340 | I1: =H1+7 -> 45347 | J1: =I1+7 -> 45354 | K1: =J1+7 -> 45361 | ... R1: =Q1+7 -> 45410 | S1: Comments
A2: Canada | B2: Client Requirement | C2: =Canada!D2+Canada!#REF!+Canada!#REF!+Canada!#REF!+Canada!#REF!+Canada!#REF! -> #VALUE! | D2: =Canada!E2+Canada!#REF!+Canada!#REF!+Canada!#REF!+Canada!#REF!+Canada!#REF! -> #REF! | E2: =Canada!F2+Canada!#REF!+Canada!#REF!+Canada!#REF!+Canada!#REF!+Canada!#REF! -> #REF! | F2: =Canada!G2+Canada!#REF!+Canada!#REF!+Canada!#REF!+Canada!#REF!+Canada!#REF! -> #REF! | G2: =Canada!H2+Canada!#REF!+Canada!#REF!+Canada!#REF!+Canada!#REF!+Canada!#REF! -> #REF! | H2: =Canada!I2+Canada!#REF!+Canada!#REF!+Canada!#REF!+Canada!#REF!+Canada!#REF! -> #REF! | I2: =Canada!J2+Canada!#REF!+Canada!#REF!+Canada!#REF!+Canada!#REF!+Canada!#REF! -> #REF! | J2: =Canada!K2+Canada!#REF!+Canada!#REF!+Canada!#REF!+Canada!#REF!+Canada!#REF! -> #REF! | ... R2: =Canada!S2+Canada!#REF!+Canada!#REF!+Canada!#REF!+Canada!#REF!+Canada!#REF! -> #REF!
B3: Projected FTE | C3: =Canada!D3+Canada!#REF!+Canada!#REF!+Canada!#REF!+Canada!#REF!+Canada!#REF! -> #VALUE! | D3: =Canada!E3+Canada!#REF!+Canada!#REF!+Canada!#REF!+Canada!#REF!+Canada!#REF! -> #REF! | E3: =Canada!F3+Canada!#REF!+Canada!#REF!+Canada!#REF!+Canada!#REF!+Canada!#REF! -> #REF! | F3: =Canada!G3+Canada!#REF!+Canada!#REF!+Canada!#REF!+Canada!#REF!+Canada!#REF! -> #REF! | G3: =Canada!H3+Canada!#REF!+Canada!#REF!+Canada!#REF!+Canada!#REF!+Canada!#REF! -> #REF! | H3: =Canada!I3+Canada!#REF!+Canada!#REF!+Canada!#REF!+Canada!#REF!+Canada!#REF! -> #REF! | I3: =Canada!J3+Canada!#REF!+Canada!#REF!+Canada!#REF!+Canada!#REF!+Canada!#REF! -> #REF! | J3: =Canada!K3+Canada!#REF!+Canada!#REF!+Canada!#REF!+Canada!#REF!+Canada!#REF! -> #REF! | ... R3: =Canada!S3+Canada!#REF!+Canada!#REF!+Canada!#REF!+Canada!#REF!+Canada!#REF! -> #REF!
B4: Staffing% | C4: =IFERROR(C3/C2,"") | D4: =IFERROR(D3/D2,"") | E4: =IFERROR(E3/E2,"") | F4: =IFERROR(F3/F2,"") | G4: =IFERROR(G3/G2,"") | H4: =IFERROR(H3/H2,"") | I4: =IFERROR(I3/I2,"") | J4: =IFERROR(J3/J2,"") | ... R4: =IFERROR(R3/R2,"")
A6: Columbia | B6: Client Requirement | C6: =#REF!+#REF!+#REF!+#REF!+#REF!+#REF!+#REF!+#REF!+#REF!+#REF!+#REF!+#REF!+#REF! -> #REF! | D6: =#REF!+#REF!+#REF!+#REF!+#REF!+#REF!+#REF!+#REF!+#REF!+#REF!+#REF!+#REF!+#REF! -> #REF! | E6: =#REF!+#REF!+#REF!+#REF!+#REF!+#REF!+#REF!+#REF!+#REF!+#REF!+#REF!+#REF!+#REF! -> #REF! | F6: =#REF!+#REF!+#REF!+#REF!+#REF!+#REF!+#REF!+#REF!+#REF!+#REF!+#REF!+#REF!+#REF! -> #REF! | G6: =#REF!+#REF!+#REF!+#REF!+#REF!+#REF!+#REF!+#REF!+#REF!+#REF!+#REF!+#REF!+#REF! -> #REF! | H6: =#REF!+#REF!+#REF!+#REF!+#REF!+#REF!+#REF!+#REF!+#REF!+#REF!+#REF!+#REF!+#REF! -> #REF! | I6: =#REF!+#REF!+#REF!+#REF!+#REF!+#REF!+#REF!+#REF!+#REF!+#REF!+#REF!+#REF!+#REF! -> #REF! | J6: =#REF!+#REF!+#REF!+#REF!+#REF!+#REF!+#REF!+#REF!+#REF!+#REF!+#REF!+#REF!+#REF! -> #REF! | ... R6: =#REF!+#REF!+#REF!+#REF!+#REF!+#REF!+#REF!+#REF!+#REF!+#REF!+#REF!+#REF!+#REF! -> #REF!
B7: Projected FTE | C7: =#REF!+#REF!+#REF!+#REF!+#REF!+#REF!+#REF!+#REF!+#REF!+#REF!+#REF!+#REF!+#REF! -> #REF! | D7: =#REF!+#REF!+#REF!+#REF!+#REF!+#REF!+#REF!+#REF!+#REF!+#REF!+#REF!+#REF!+#REF! -> #REF! | E7: =#REF!+#REF!+#REF!+#REF!+#REF!+#REF!+#REF!+#REF!+#REF!+#REF!+#REF!+#REF!+#REF! -> #REF! | F7: =#REF!+#REF!+#REF!+#REF!+#REF!+#REF!+#REF!+#REF!+#REF!+#REF!+#REF!+#REF!+#REF! -> #REF! | G7: =#REF!+#REF!+#REF!+#REF!+#REF!+#REF!+#REF!+#REF!+#REF!+#REF!+#REF!+#REF!+#REF! -> #REF! | H7: =#REF!+#REF!+#REF!+#REF!+#REF!+#REF!+#REF!+#REF!+#REF!+#REF!+#REF!+#REF!+#REF! -> #REF! | I7: =#REF!+#REF!+#REF!+#REF!+#REF!+#REF!+#REF!+#REF!+#REF!+#REF!+#REF!+#REF!+#REF! -> #REF! | J7: =#REF!+#REF!+#REF!+#REF!+#REF!+#REF!+#REF!+#REF!+#REF!+#REF!+#REF!+#REF!+#REF! -> #REF! | ... R7: =#REF!+#REF!+#REF!+#REF!+#REF!+#REF!+#REF!+#REF!+#REF!+#REF!+#REF!+#REF!+#REF! -> #REF!
B8: Staffing% | C8: =IFERROR(C7/C6,"") | D8: =IFERROR(D7/D6,"") | E8: =IFERROR(E7/E6,"") | F8: =IFERROR(F7/F6,"") | G8: =IFERROR(G7/G6,"") | H8: =IFERROR(H7/H6,"") | I8: =IFERROR(I7/I6,"") | J8: =IFERROR(J7/J6,"") | ... R8: =IFERROR(R7/R6,"")
A10: Egypt | B10: Client Requirement | C10: =#REF!+#REF! -> #REF! | D10: =#REF!+#REF! -> #REF! | E10: =#REF!+#REF! -> #REF! | F10: =#REF!+#REF! -> #REF! | G10: =#REF!+#REF! -> #REF! | H10: =#REF!+#REF! -> #REF! | I10: =#REF!+#REF! -> #REF! | J10: =#REF!+#REF! -> #REF! | ... R10: =#REF!+#REF! -> #REF!
B11: Projected FTE | C11: =#REF!+#REF! -> #REF! | D11: =#REF!+#REF! -> #REF! | E11: =#REF!+#REF! -> #REF! | F11: =#REF!+#REF! -> #REF! | G11: =#REF!+#REF! -> #REF! | H11: =#REF!+#REF! -> #REF! | I11: =#REF!+#REF! -> #REF! | J11: =#REF!+#REF! -> #REF! | ... R11: =#REF!+#REF! -> #REF!
B12: Staffing% | C12: =IFERROR(C11/C10,"") | D12: =IFERROR(D11/D10,"") | E12: =IFERROR(E11/E10,"") | F12: =IFERROR(F11/F10,"") | G12: =IFERROR(G11/G10,"") | H12: =IFERROR(H11/H10,"") | I12: =IFERROR(I11/I10,"") | J12: =IFERROR(J11/J10,"") | ... R12: =IFERROR(R11/R10,"")
A14: Philippines | B14: Client Requirement | C14: =#REF!+#REF!+#REF!+#REF!+#REF!+#REF!+#REF!+#REF!+#REF!+#REF!+#REF!+#REF!+#REF!+#REF!+#REF!+#REF!+#REF!+#REF!+#REF!+#REF! -> #REF! | D14: =#REF!+#REF!+#REF!+#REF!+#REF!+#REF!+#REF!+#REF!+#REF!+#REF!+#REF!+#REF!+#REF!+#REF!+#REF!+#REF!+#REF!+#REF!+#REF!+#REF! -> #REF! | E14: =#REF!+#REF!+#REF!+#REF!+#REF!+#REF!+#REF!+#REF!+#REF!+#REF!+#REF!+#REF!+#REF!+#REF!+#REF!+#REF!+#REF!+#REF!+#REF!+#REF! -> #REF! | F14: =#REF!+#REF!+#REF!+#REF!+#REF!+#REF!+#REF!+#REF!+#REF!+#REF!+#REF!+#REF!+#REF!+#REF!+#REF!+#REF!+#REF!+#REF!+#REF!+#REF! -> #REF! | G14: =#REF!+#REF!+#REF!+#REF!+#REF!+#REF!+#REF!+#REF!+#REF!+#REF!+#REF!+#REF!+#REF!+#REF!+#REF!+#REF!+#REF!+#REF!+#REF!+#REF! -> #REF! | H14: =#REF!+#REF!+#REF!+#REF!+#REF!+#REF!+#REF!+#REF!+#REF!+#REF!+#REF!+#REF!+#REF!+#REF!+#REF!+#REF!+#REF!+#REF!+#REF!+#REF! -> #REF! | I14: =#REF!+#REF!+#REF!+#REF!+#REF!+#REF!+#REF!+#REF!+#REF!+#REF!+#REF!+#REF!+#REF!+#REF!+#REF!+#REF!+#REF!+#REF!+#REF!+#REF! -> #REF! | J14: =#REF!+#REF!+#REF!+#REF!+#REF!+#REF!+#REF!+#REF!+#REF!+#REF!+#REF!+#REF!+#REF!+#REF!+#REF!+#REF!+#REF!+#REF!+#REF!+#REF! -> #REF! | ... R14: =#REF!+#REF!+#REF!+#REF!+#REF!+#REF!+#REF!+#REF!+#REF!+#REF!+#REF!+#REF!+#REF!+#REF!+#REF!+#REF!+#REF!+#REF!+#REF!+#REF! -> #REF!
B15: Projected FTE | C15: =#REF!+#REF!+#REF!+#REF!+#REF!+#REF!+#REF!+#REF!+#REF!+#REF!+#REF!+#REF!+#REF!+#REF!+#REF!+#REF!+#REF!+#REF!+#REF!+#REF! -> #REF! | D15: =#REF!+#REF!+#REF!+#REF!+#REF!+#REF!+#REF!+#REF!+#REF!+#REF!+#REF!+#REF!+#REF!+#REF!+#REF!+#REF!+#REF!+#REF!+#REF!+#REF! -> #REF! | E15: =#REF!+#REF!+#REF!+#REF!+#REF!+#REF!+#REF!+#REF!+#REF!+#REF!+#REF!+#REF!+#REF!+#REF!+#REF!+#REF!+#REF!+#REF!+#REF!+#REF! -> #REF! | F15: =#REF!+#REF!+#REF!+#REF!+#REF!+#REF!+#REF!+#REF!+#REF!+#REF!+#REF!+#REF!+#REF!+#REF!+#REF!+#REF!+#REF!+#REF!+#REF!+#REF! -> #REF! | G15: =#REF!+#REF!+#REF!+#REF!+#REF!+#REF!+#REF!+#REF!+#REF!+#REF!+#REF!+#REF!+#REF!+#REF!+#REF!+#REF!+#REF!+#REF!+#REF!+#REF! -> #REF! | H15: =#REF!+#REF!+#REF!+#REF!+#REF!+#REF!+#REF!+#REF!+#REF!+#REF!+#REF!+#REF!+#REF!+#REF!+#REF!+#REF!+#REF!+#REF!+#REF!+#REF! -> #REF! | I15: =#REF!+#REF!+#REF!+#REF!+#REF!+#REF!+#REF!+#REF!+#REF!+#REF!+#REF!+#REF!+#REF!+#REF!+#REF!+#REF!+#REF!+#REF!+#REF!+#REF! -> #REF! | J15: =#REF!+#REF!+#REF!+#REF!+#REF!+#REF!+#REF!+#REF!+#REF!+#REF!+#REF!+#REF!+#REF!+#REF!+#REF!+#REF!+#REF!+#REF!+#REF!+#REF! -> #REF! | ... R15: =#REF!+#REF!+#REF!+#REF!+#REF!+#REF!+#REF!+#REF!+#REF!+#REF!+#REF!+#REF!+#REF!+#REF!+#REF!+#REF!+#REF!+#REF!+#REF!+#REF! -> #REF!
B16: Staffing% | C16: =IFERROR(C15/C14,"") | D16: =IFERROR(D15/D14,"") | E16: =IFERROR(E15/E14,"") | F16: =IFERROR(F15/F14,"") | G16: =IFERROR(G15/G14,"") | H16: =IFERROR(H15/H14,"") | I16: =IFERROR(I15/I14,"") | J16: =IFERROR(J15/J14,"") | ... R16: =IFERROR(R15/R14,"")
A18: India | B18: Client Requirement | C18: =#REF!+#REF! -> #REF! | D18: =#REF!+#REF! -> #REF! | E18: =#REF!+#REF! -> #REF! | F18: =#REF!+#REF! -> #REF! | G18: =#REF!+#REF! -> #REF! | H18: =#REF!+#REF! -> #REF! | I18: =#REF!+#REF! -> #REF! | J18: =#REF!+#REF! -> #REF! | ... R18: =#REF!+#REF! -> #REF!
B19: Projected FTE | C19: =#REF!+#REF! -> #REF! | D19: =#REF!+#REF! -> #REF! | E19: =#REF!+#REF! -> #REF! | F19: =#REF!+#REF! -> #REF! | G19: =#REF!+#REF! -> #REF! | H19: =#REF!+#REF! -> #REF! | I19: =#REF!+#REF! -> #REF! | J19: =#REF!+#REF! -> #REF! | ... R19: =#REF!+#REF! -> #REF!
B20: Staffing% | C20: =IFERROR(C19/C18,"") | D20: =IFERROR(D19/D18,"") | E20: =IFERROR(E19/E18,"") | F20: =IFERROR(F19/F18,"") | G20: =IFERROR(G19/G18,"") | H20: =IFERROR(H19/H18,"") | I20: =IFERROR(I19/I18,"") | J20: =IFERROR(J19/J18,"") | ... R20: =IFERROR(R19/R18,"")
A22: US | B22: Client Requirement | C22: =US!E2+US!#REF!+US!#REF!+US!#REF! -> #REF! | D22: =US!F2+US!#REF!+US!#REF!+US!#REF! -> #REF! | E22: =US!G2+US!#REF!+US!#REF!+US!#REF! -> #REF! | F22: =US!H2+US!#REF!+US!#REF!+US!#REF! -> #REF! | G22: =US!I2+US!#REF!+US!#REF!+US!#REF! -> #REF! | H22: =US!J2+US!#REF!+US!#REF!+US!#REF! -> #REF! | I22: =US!K2+US!#REF!+US!#REF!+US!#REF! -> #REF! | J22: =US!L2+US!#REF!+US!#REF!+US!#REF! -> #REF! | ... R22: =US!T2+US!#REF!+US!#REF!+US!#REF! -> #REF!
B23: Projected FTE | C23: =US!E3+US!#REF!+US!#REF!+US!#REF! -> #REF! | D23: =US!F3+US!#REF!+US!#REF!+US!#REF! -> #REF! | E23: =US!G3+US!#REF!+US!#REF!+US!#REF! -> #REF! | F23: =US!H3+US!#REF!+US!#REF!+US!#REF! -> #REF! | G23: =US!I3+US!#REF!+US!#REF!+US!#REF! -> #REF! | H23: =US!J3+US!#REF!+US!#REF!+US!#REF! -> #REF! | I23: =US!K3+US!#REF!+US!#REF!+US!#REF! -> #REF! | J23: =US!L3+US!#REF!+US!#REF!+US!#REF! -> #REF! | ... R23: =US!T3+US!#REF!+US!#REF!+US!#REF! -> #REF!
B24: Staffing% | C24: =IFERROR(C23/C22,"") | D24: =IFERROR(D23/D22,"") | E24: =IFERROR(E23/E22,"") | F24: =IFERROR(F23/F22,"") | G24: =IFERROR(G23/G22,"") | H24: =IFERROR(H23/H22,"") | I24: =IFERROR(I23/I22,"") | J24: =IFERROR(J23/J22,"") | ... R24: =IFERROR(R23/R22,"")
A26: Mexico | B26: Client Requirement | C26: =#REF!+#REF!+#REF!+#REF!+#REF!+#REF!+#REF!+#REF!+#REF! -> #REF! | D26: =#REF!+#REF!+#REF!+#REF!+#REF!+#REF!+#REF!+#REF!+#REF! -> #REF! | E26: =#REF!+#REF!+#REF!+#REF!+#REF!+#REF!+#REF!+#REF!+#REF! -> #REF! | F26: =#REF!+#REF!+#REF!+#REF!+#REF!+#REF!+#REF!+#REF!+#REF! -> #REF! | G26: =#REF!+#REF!+#REF!+#REF!+#REF!+#REF!+#REF!+#REF!+#REF! -> #REF! | H26: =#REF!+#REF!+#REF!+#REF!+#REF!+#REF!+#REF!+#REF!+#REF! -> #REF! | I26: =#REF!+#REF!+#REF!+#REF!+#REF!+#REF!+#REF!+#REF!+#REF! -> #REF! | J26: =#REF!+#REF!+#REF!+#REF!+#REF!+#REF!+#REF!+#REF!+#REF! -> #REF! | ... R26: =#REF!+#REF!+#REF!+#REF!+#REF!+#REF!+#REF!+#REF!+#REF! -> #REF!
B27: Projected FTE | C27: =#REF!+#REF!+#REF!+#REF!+#REF!+#REF!+#REF!+#REF!+#REF! -> #REF! | D27: =#REF!+#REF!+#REF!+#REF!+#REF!+#REF!+#REF!+#REF!+#REF! -> #REF! | E27: =#REF!+#REF!+#REF!+#REF!+#REF!+#REF!+#REF!+#REF!+#REF! -> #REF! | F27: =#REF!+#REF!+#REF!+#REF!+#REF!+#REF!+#REF!+#REF!+#REF! -> #REF! | G27: =#REF!+#REF!+#REF!+#REF!+#REF!+#REF!+#REF!+#REF!+#REF! -> #REF! | H27: =#REF!+#REF!+#REF!+#REF!+#REF!+#REF!+#REF!+#REF!+#REF! -> #REF! | I27: =#REF!+#REF!+#REF!+#REF!+#REF!+#REF!+#REF!+#REF!+#REF! -> #REF! | J27: =#REF!+#REF!+#REF!+#REF!+#REF!+#REF!+#REF!+#REF!+#REF! -> #REF! | ... R27: =#REF!+#REF!+#REF!+#REF!+#REF!+#REF!+#REF!+#REF!+#REF! -> #REF!
B28: Staffing% | C28: =IFERROR(C27/C26,"") | D28: =IFERROR(D27/D26,"") | E28: =IFERROR(E27/E26,"") | F28: =IFERROR(F27/F26,"") | G28: =IFERROR(G27/G26,"") | H28: =IFERROR(H27/H26,"") | I28: =IFERROR(I27/I26,"") | J28: =IFERROR(J27/J26,"") | ... R28: =IFERROR(R27/R26,"")
A30: Jamaica | B30: Client Requirement | C30: =#REF!+#REF!+#REF!+#REF!+#REF! -> #REF! | D30: =#REF!+#REF!+#REF!+#REF!+#REF! -> #REF! | E30: =#REF!+#REF!+#REF!+#REF!+#REF! -> #REF! | F30: =#REF!+#REF!+#REF!+#REF!+#REF! -> #REF! | G30: =#REF!+#REF!+#REF!+#REF!+#REF! -> #REF! | H30: =#REF!+#REF!+#REF!+#REF!+#REF! -> #REF! | I30: =#REF!+#REF!+#REF!+#REF!+#REF! -> #REF! | J30: =#REF!+#REF!+#REF!+#REF!+#REF! -> #REF! | ... R30: =#REF!+#REF!+#REF!+#REF!+#REF! -> #REF!
B31: Projected FTE | C31: =#REF!+#REF!+#REF!+#REF!+#REF! -> #REF! | D31: =#REF!+#REF!+#REF!+#REF!+#REF! -> #REF! | E31: =#REF!+#REF!+#REF!+#REF!+#REF! -> #REF! | F31: =#REF!+#REF!+#REF!+#REF!+#REF! -> #REF! | G31: =#REF!+#REF!+#REF!+#REF!+#REF! -> #REF! | H31: =#REF!+#REF!+#REF!+#REF!+#REF! -> #REF! | I31: =#REF!+#REF!+#REF!+#REF!+#REF! -> #REF! | J31: =#REF!+#REF!+#REF!+#REF!+#REF! -> #REF! | ... R31: =#REF!+#REF!+#REF!+#REF!+#REF! -> #REF!
B32: Staffing% | C32: =IFERROR(C31/C30,"") | D32: =IFERROR(D31/D30,"") | E32: =IFERROR(E31/E30,"") | F32: =IFERROR(F31/F30,"") | G32: =IFERROR(G31/G30,"") | H32: =IFERROR(H31/H30,"") | I32: =IFERROR(I31/I30,"") | J32: =IFERROR(J31/J30,"") | ... R32: =IFERROR(R31/R30,"")

Sheet Canada
A1: H2R Department | B1: Client Name | C1: Country | E1: 45340 | F1: =E1+7 -> 45347 | G1: =F1+7 -> 45354 | H1: =G1+7 -> 45361 | I1: =H1+7 -> 45368 | J1: =I1+7 -> 45375 | K1: =J1+7 -> 45382 | L1: =K1+7 -> 45389 | M1: =L1+7 -> 45396 | ... EY1: =EX1+7 -> 46390
A2: Door Dash | B2: DoorDash Montreal | C2: Canada | D2: Budget | Q2: 21 | R2: 28 | S2: 28 | T2: 28 | U2: 28 | V2: 28 | W2: 28 | X2: 28 | Y2: 28 | Z2: 28 | AA2: 28 | AB2: 28 | AC2: 28 | AD2: 28 | AE2: 28 | AF2: 28 | AG2: 28 | AH2: 28 | AI2: 28 | AJ2: 28 | AK2: 28 | AL2: 28 | AM2: 28 | AN2: 28 | AO2: 28 | AP2: 28 | AQ2: 28 | AR2: 28 | AS2: 28 | AT2: 28 | AU2: =AT2 -> 28 | AV2: =AU2 -> 28 | AW2: 28
D3: Forecast | P3: 0 | Q3: 22 | R3: 22 | S3: 22 | T3: 11 | U3: 21 | V3: 21 | W3: 17 | X3: 28 | Y3: 24 | Z3: 27 | AA3: 27 | AB3: 27 | AC3: 25 | AD3: 27 | AE3: 19 | AF3: 11 | AG3: 19 | AH3: 17 | AI3: 17 | AJ3: 27 | AK3: 27 | AL3: 27 | AM3: 27 | AN3: 27 | AO3: 30 | AP3: 30 | AQ3: 27 | AR3: 27 | AS3: 31 | AT3: 27 | AU3: 27 | AV3: 27 | AW3: 30 | AX3: 31 | AY3: 27 | AZ3: 27 | BA3: 27 | BB3: 27 | BC3: 27 | BD3: 27 | BE3: 27 | BF3: 27 | BG3: 27 | BH3: 27 | BI3: 27 | BJ3: 28 | BK3: 28 | BL3: 28 | BM3: 27 | BN3: 28 | BO3: 27 | BP3: 25 | BQ3: 25 | BR3: 24 | BS3: 23 | BT3: 23 | BU3: 23 | BV3: 22 | BW3: 22 | BX3: 9
D4: Required | P4: 19.55 | Q4: 18.7 | R4: 18.513 | S4: 20.196 | T4: 10.098 | U4: 20.0376 | V4: 29.6208 | W4: 16 | X4: 25 | Y4: 24 | Z4: 24 | AA4: 24 | AB4: 22 | AC4: 19 | AD4: 28 | AE4: 12 | AF4: 21 | AG4: 21 | AH4: 17 | AI4: 16 | AJ4: 23 | AK4: 22 | AL4: 22 | AM4: 21 | AN4: 20 | AO4: 20 | AP4: 20 | AQ4: 20 | AR4: 27 | AS4: 34 | AT4: 34 | AU4: 36 | AV4: 34 | AW4: 34 | AX4: 34 | AY4: 33 | AZ4: 31 | BA4: 30 | BB4: 30 | BC4: 29 | BD4: 27 | BE4: 27 | BF4: 25 | BG4: 29 | BH4: 28 | BI4: 28 | BJ4: 29 | BK4: 30 | BL4: 29 | BM4: 25 | BN4: 26 | BO4: 25 | BP4: 24 | BQ4: 22 | BR4: 21 | BS4: 21 | BT4: 20 | BU4: 18 | BV4: 17 | BW4: 16 | BX4: 14
D5: Projected | AA5: 27 | AB5: 26 | AC5: 22 | AD5: 34 | AE5: 14 | AF5: 25 | AG5: 25 | AH5: 30 | AI5: 29 | AJ5: 29 | AK5: 28 | AL5: 27 | AM5: 26 | AN5: 26 | AO5: 26 | AP5: 26 | AQ5: 25 | AR5: 46 | AS5: 46 | AT5: 44 | AU5: 44 | AV5: 43 | AW5: 42 | AX5: 42 | AY5: 40 | AZ5: 38 | BA5: 37 | BB5: 37 | BC5: 36 | BD5: 34 | BE5: 33 | BF5: 31 | BG5: 31 | BH5: 31 | BI5: 31 | BJ5: 31 | BK5: 33 | BL5: 33 | BM5: 31 | BN5: 30 | BO5: 29 | BP5: 28 | BQ5: 26 | BR5: 25 | BS5: 24 | BT5: 23 | BU5: 21 | BV5: 20 | BW5: 19 | BX5: 17
D6: Budget Vs Actual | E6: =E4/E2 -> #DIV/0! | F6: =F4/F2 -> #DIV/0! | G6: =G4/G2 -> #DIV/0! | H6: =H4/H2 -> #DIV/0! | I6: =I4/I2 -> #DIV/0! | J6: =J4/J2 -> #DIV/0! | K6: =K4/K2 -> #DIV/0! | L6: =L4/L2 -> #DIV/0! | ... EY6: =EY4/EY2 -> #DIV/0!
D7: Forecast Vs Actual | E7: =E4/E3 -> #DIV/0! | F7: =F4/F3 -> #DIV/0! | G7: =G4/G3 -> #DIV/0! | H7: =H4/H3 -> #DIV/0! | I7: =I4/I3 -> #DIV/0! | J7: =J4/J3 -> #DIV/0! | K7: =K4/K3 -> #DIV/0! | L7: =L4/L3 -> #DIV/0! | ... AA7: =AA4/AA3 -> 0.88888889 | AB7: =AB5/AB3 -> 0.96296296 | AC7: =AC5/AC3 -> 0.88 | AD7: =AD5/AD3 -> 1.2592593 | AE7: =AE5/AE3 -> 0.73684211 | AF7: =AF5/AF3 -> 2.2727273 | AG7: =AG5/AG3 -> 1.3157895 | AH7: =AH5/AH3 -> 1.7647059 | AI7: =AI5/AI3 -> 1.7058824 | ... AR7: =AR5/AR3 -> 1.7037037 | AS7: =AS4/AS3 -> 1.0967742 | AT7: =AT4/AT3 -> 1.2592593 | AU7: =AU4/AU3 -> 1.3333333 | AV7: =AV4/AV3 -> 1.2592593 | AW7: =AW4/AW3 -> 1.1333333 | AX7: =AX4/AX3 -> 1.0967742 | AY7: =AY4/AY3 -> 1.2222222 | AZ7: =AZ4/AZ3 -> 1.1481481 | ... EY7: =EY4/EY3 -> #DIV/0!
A9: Hard Rock Hotels and Casino | B9: Hard Rock | C9: Canada | D9: Budget
D10: Forecast | BT10: 10 | BU10: 7 | BV10: 10 | BW10: 10 | BX10: 10 | BY10: 10 | BZ10: 10 | CA10: 10 | CB10: 9 | CC10: 9 | CD10: 9 | CE10: 9 | CF10: 9 | CG10: 9 | CH10: 9 | CI10: 9 | CJ10: 9 | CK10: 9 | CL10: 9 | CM10: 9 | CN10: 9 | CO10: 9 | CP10: 9 | CQ10: 9 | CR10: 9 | CS10: 9 | CT10: 9 | CU10: 9 | CV10: 9 | CW10: 9 | CX10: 9 | CY10: 9 | CZ10: 9 | DA10: 9 | DB10: 9 | DC10: 9 | DD10: 9 | DE10: 9 | DF10: 9 | DG10: 9 | DH10: 9 | DI10: 21 | DJ10: 21 | DK10: 21 | DL10: 34 | DM10: 33 | DN10: 30 | DO10: 34 | DP10: 34 | DQ10: 33 | DR10: 33 | DS10: 33 | DT10: 33 | DU10: 33 | DV10: 32 | DW10: 32 | DX10: 32 | DY10: 30 | DZ10: 30 | EA10: 30 | EB10: 30 | EC10: 30 | ED10: 30 | EE10: 30 | EF10: 30 | EG10: 30 | EH10: 30 | EI10: 30 | EJ10: 30 | EK10: 30 | EL10: 30 | EM10: 30 | EN10: 30 | EO10: 30 | EP10: 30 | EQ10: 30 | ER10: 30 | ES10: 30 | ET10: 30 | EU10: 9 | EV10: 9 | EW10: 9 | EX10: 9 | EY10: 9
D11: Required | BT11: 10 | BU11: 7 | BV11: 6 | BW11: 6 | BX11: 9.4 | BY11: 15 | BZ11: 14 | CA11: 14 | CB11: 14 | CC11: 13 | CD11: =CD10*1.1 -> 9.9 | CE11: =CE10*1.1 -> 9.9 | CF11: 13 | CG11: 13 | CH11: 12 | CI11: 13 | CJ11: 13 | CK11: 13 | CL11: 12 | CM11: 12 | CN11: 12 | CO11: 12 | CP11: 11 | CQ11: 9 | CR11: 10 | CS11: 10 | CT11: 11 | CU11: 11 | CV11: 11 | CW11: 11 | CX11: 10 | CY11: 10 | CZ11: 10 | DA11: 10 | DB11: 10 | DC11: 10 | DD11: 10 | DE11: 9 | DF11: 8 | DG11: 7 | DH11: 8 | DI11: 24 | DJ11: 28 | DK11: 18 | DL11: 34 | DM11: 42.5 | DN11: 42.5 | DO11: 36 | DP11: 34 | DQ11: 31 | DR11: 35 | DS11: 30 | DT11: 30 | DU11: 30 | DV11: 37 | DW11: 37 | DX11: 39 | DY11: 36 | DZ11: 33 | EA11: 33 | EB11: 40 | EC11: 39 | ED11: 38 | EE11: 36 | EF11: 43.57 | EG11: 41.57 | EH11: 39.57 | EI11: 37.57 | EJ11: 35.57 | EK11: 33.57 | EL11: 40.251904 | EM11: 38.251904 | EN11: 36.251904 | EO11: 34.251904 | EP11: 32.251904 | EQ11: 30.251904 | ER11: 36.933808 | ES11: 34.933808 | ET11: 32.933808 | EU11: 7.85439 | EV11: 7.85439 | EW11: 7.85439 | EX11: 7.85439 | EY11: 8.26216
D12: Projected | BT12: 8 | BU12: =BU11 -> 7 | BV12: 6 | BW12: 6 | BX12: 8.89 | BY12: 8.89 | BZ12: 11.336975 | CA12: 11.336975 | CB12: 11.336975 | CC12: =CC11 -> 13 | CD12: 13 | CE12: 13 | CF12: 13 | CG12: 13 | CH12: 12 | CI12: 12 | CJ12: 12 | CK12: 12 | CL12: 11 | CM12: 11 | CN12: 11 | CO12: 11 | CP12: 10 | CQ12: 10 | CR12: 10 | CS12: =CS11 -> 10 | CT12: =CT11 -> 11 | CU12: =CU11 -> 11 | CV12: =CV11 -> 11 | CW12: =CW11 -> 11 | CX12: =CX11 -> 10 | CY12: =CY11 -> 10 | CZ12: =CZ11 -> 10 | ... EY12: =EY11 -> 8.26216
D13: Budget Vs Actual | E13: =E11/E9 -> #DIV/0! | F13: =F11/F9 -> #DIV/0! | G13: =G11/G9 -> #DIV/0! | H13: =H11/H9 -> #DIV/0! | I13: =I11/I9 -> #DIV/0! | J13: =J11/J9 -> #DIV/0! | K13: =K11/K9 -> #DIV/0! | L13: =L11/L9 -> #DIV/0! | ... EY13: =EY11/EY9 -> #DIV/0!
D14: Forecast Vs Actual | E14: =E11/E10 -> #DIV/0! | F14: =F11/F10 -> #DIV/0! | G14: =G11/G10 -> #DIV/0! | H14: =H11/H10 -> #DIV/0! | I14: =I11/I10 -> #DIV/0! | J14: =J11/J10 -> #DIV/0! | K14: =K11/K10 -> #DIV/0! | L14: =L11/L10 -> #DIV/0! | ... AA14: =AA11/AA10 -> #DIV/0! | AB14: =AB12/AB10 -> #DIV/0! | AC14: =AC12/AC10 -> #DIV/0! | AD14: =AD12/AD10 -> #DIV/0! | AE14: =AE12/AE10 -> #DIV/0! | AF14: =AF12/AF10 -> #DIV/0! | AG14: =AG12/AG10 -> #DIV/0! | AH14: =AH12/AH10 -> #DIV/0! | AI14: =AI12/AI10 -> #DIV/0! | ... AR14: =AR12/AR10 -> #DIV/0! | AS14: =AS11/AS10 -> #DIV/0! | AT14: =AT11/AT10 -> #DIV/0! | AU14: =AU11/AU10 -> #DIV/0! | AV14: =AV11/AV10 -> #DIV/0! | AW14: =AW11/AW10 -> #DIV/0! | AX14: =AX11/AX10 -> #DIV/0! | AY14: =AY11/AY10 -> #DIV/0! | AZ14: =AZ11/AZ10 -> #DIV/0! | ... EY14: =EY11/EY10 -> 0.91801778
A16: CAA | B16: CAA | C16: Canada | D16: Budget
D17: Forecast | CG17: 26 | CH17: 26 | CI17: 23 | CJ17: 23 | CK17: 23 | CL17: 23 | CM17: 23 | CN17: 23 | CO17: 23 | CP17: 23 | CQ17: 23 | CR17: 23 | CS17: 23 | CT17: 23 | CU17: 23 | CV17: 23 | CW17: 23 | CX17: 23 | CY17: 23 | CZ17: 23 | DA17: 23 | DB17: 23 | DC17: 23 | DD17: 23 | DE17: 23 | DF17: 23 | DG17: 23 | DH17: 23 | DI17: 23 | DJ17: 23 | DK17: 23 | DL17: 23 | DM17: 23 | DN17: 23 | DO17: 23 | DP17: 23 | DQ17: 23 | DR17: 23 | DS17: 23 | DT17: 23 | DU17: 23 | DV17: 23 | DW17: 23 | DX17: 23 | DY17: 23 | DZ17: 15 | EA17: 15 | EB17: 15 | EC17: 15 | ED17: 15 | EE17: 15 | EF17: 15 | EG17: 15 | EH17: 15 | EI17: 15 | EJ17: 15 | EK17: 15 | EL17: 15 | EM17: 15 | EN17: 15 | EO17: 15 | EP17: 15 | EQ17: 15 | ER17: 15 | ES17: 15 | ET17: 15 | EU17: 23 | EV17: 23 | EW17: 23 | EX17: 23 | EY17: 23
D18: Required | CG18: 14 | CH18: 22.4 | CI18: 24 | CJ18: 22 | CK18: 21 | CL18: 21 | CM18: 21 | CN18: 19 | CO18: 26 | CP18: 26 | CQ18: 25 | CR18: 25 | CS18: 23 | CT18: 23 | CU18: 21 | CV18: 21 | CW18: 26 | CX18: 25 | CY18: 24 | CZ18: 22 | DA18: 22 | DB18: 22 | DC18: 22 | DD18: 22 | DE18: 31 | DF18: 31 | DG18: 31 | DH18: 29 | DI18: 29 | DJ18: 28 | DK18: 28 | DL18: 27 | DM18: 26.657 | DN18: 27.025 | DO18: 27.094 | DP18: 27.37 | DQ18: 26.542 | DR18: 26.542 | DS18: 27.37 | DT18: 28.175 | DU18: 28.175 | DV18: 28.175 | DW18: 28.129 | DX18: 28.129 | DY18: 27.301 | DZ18: 17.3955 | EA18: 17.3955 | EB18: 17.3955 | EC18: 17.3955 | ED18: 17.3955 | EE18: 17.3955 | EF18: 17.3955 | EG18: 17.3955 | EH18: 17.3955 | EI18: 17.3955 | EJ18: 17.3955 | EK18: 17.3955 | EL18: 17.3955 | EM18: 17.3955 | EN18: 17.3955 | EO18: 17.3955 | EP18: 17.3955 | EQ18: 17.3955 | ER18: 17.3955 | ES18: 17.3955 | ET18: 17.3955 | EU18: 23.535825 | EV18: 22.535825 | EW18: 22.535825 | EX18: 21.535825 | EY18: 21.535825
D19: Projected | CG19: =CG18 -> 14 | CH19: =CH18 -> 22.4 | CI19: =CI18 -> 24 | CJ19: =CJ18 -> 22 | CK19: =CK18 -> 21 | CL19: =CL18 -> 21 | CM19: =CM18 -> 21 | CN19: =CN18 -> 19 | ... EY19: =EY18 -> 21.535825
D20: Budget Vs Actual | E20: =E18/E16 -> #DIV/0! | F20: =F18/F16 -> #DIV/0! | G20: =G18/G16 -> #DIV/0! | H20: =H18/H16 -> #DIV/0! | I20: =I18/I16 -> #DIV/0! | J20: =J18/J16 -> #DIV/0! | K20: =K18/K16 -> #DIV/0! | L20: =L18/L16 -> #DIV/0! | ... EY20: =EY18/EY16 -> #DIV/0!
D21: Forecast Vs Actual | E21: =E18/E17 -> #DIV/0! | F21: =F18/F17 -> #DIV/0! | G21: =G18/G17 -> #DIV/0! | H21: =H18/H17 -> #DIV/0! | I21: =I18/I17 -> #DIV/0! | J21: =J18/J17 -> #DIV/0! | K21: =K18/K17 -> #DIV/0! | L21: =L18/L17 -> #DIV/0! | ... AA21: =AA18/AA17 -> #DIV/0! | AB21: =AB19/AB17 -> #DIV/0! | AC21: =AC19/AC17 -> #DIV/0! | AD21: =AD19/AD17 -> #DIV/0! | AE21: =AE19/AE17 -> #DIV/0! | AF21: =AF19/AF17 -> #DIV/0! | AG21: =AG19/AG17 -> #DIV/0! | AH21: =AH19/AH17 -> #DIV/0! | AI21: =AI19/AI17 -> #DIV/0! | ... AR21: =AR19/AR17 -> #DIV/0! | AS21: =AS18/AS17 -> #DIV/0! | AT21: =AT18/AT17 -> #DIV/0! | AU21: =AU18/AU17 -> #DIV/0! | AV21: =AV18/AV17 -> #DIV/0! | AW21: =AW18/AW17 -> #DIV/0! | AX21: =AX18/AX17 -> #DIV/0! | AY21: =AY18/AY17 -> #DIV/0! | AZ21: =AZ18/AZ17 -> #DIV/0! | ... EY21: =EY18/EY17 -> 0.93634022
A23: Caillac Fairview | B23: Cadillac | C23: Canada | D23: Budget
D24: Forecast | DE24: 14.5 | DF24: 14.5 | DG24: 14.5 | DH24: 14.5 | DI24: 14.5 | DJ24: 14.5 | DK24: 14.5 | DL24: 14.5 | DM24: 14.5 | DN24: 14.5 | DO24: 14.5 | DP24: 14.5 | DQ24: 14.5 | DR24: 14.5 | DS24: 14.5 | DT24: 14.5 | DU24: 14.5 | DV24: 14.5 | DW24: 14.5 | DX24: 14.5 | DY24: 14.5 | DZ24: 14.5 | EA24: 14.5 | EB24: 14.5 | EC24: 14.5 | ED24: 14.5 | EE24: 14.5 | EF24: 14.5 | EG24: 14.5 | EH24: 14.5 | EI24: 14.5 | EJ24: 14.5 | EK24: 14.5 | EL24: 14.5 | EM24: 14.5 | EN24: 14.5 | EO24: 14.5 | EP24: 14.5 | EQ24: 14.5 | ER24: 14.5 | ES24: 14.5 | ET24: 14.5
D25: Required | DE25: 15 | DF25: 14 | DG25: 15 | DH25: 13 | DI25: 13 | DJ25: 12 | DK25: 11 | DL25: 17 | DM25: 17 | DN25: 17 | DO25: 17 | DP25: 17 | DQ25: 17 | DR25: 17 | DS25: 17 | DT25: 17 | DU25: 17 | DV25: 17 | DW25: 17 | DX25: 15 | DY25: 16 | DZ25: 16 | EA25: 14 | EB25: 14 | EC25: 18 | ED25: 18 | EE25: 18 | EF25: 18 | EG25: 18 | EH25: 18 | EI25: 18 | EJ25: 18 | EK25: 17 | EL25: 17 | EM25: 17 | EN25: 17 | EO25: 16 | EP25: 16 | EQ25: 16 | ER25: 16 | ES25: 15 | ET25: 17.928893
D26: Projected | DE26: =DE25 -> 15 | DF26: =DF25 -> 14 | DG26: =DG25 -> 15 | DH26: =DH25 -> 13 | DI26: =DI25 -> 13 | DJ26: =DJ25 -> 12 | DK26: =DK25 -> 11 | DL26: =DL25 -> 17 | ... EY26: =EY25 -> 0
D27: Budget Vs Actual | E27: =E25/E23 -> #DIV/0! | F27: =F25/F23 -> #DIV/0! | G27: =G25/G23 -> #DIV/0! | H27: =H25/H23 -> #DIV/0! | I27: =I25/I23 -> #DIV/0! | J27: =J25/J23 -> #DIV/0! | K27: =K25/K23 -> #DIV/0! | L27: =L25/L23 -> #DIV/0! | ... EY27: =EY25/EY23 -> #DIV/0!
D28: Forecast Vs Actual | E28: =E25/E24 -> #DIV/0! | F28: =F25/F24 -> #DIV/0! | G28: =G25/G24 -> #DIV/0! | H28: =H25/H24 -> #DIV/0! | I28: =I25/I24 -> #DIV/0! | J28: =J25/J24 -> #DIV/0! | K28: =K25/K24 -> #DIV/0! | L28: =L25/L24 -> #DIV/0! | ... AA28: =AA25/AA24 -> #DIV/0! | AB28: =AB26/AB24 -> #DIV/0! | AC28: =AC26/AC24 -> #DIV/0! | AD28: =AD26/AD24 -> #DIV/0! | AE28: =AE26/AE24 -> #DIV/0! | AF28: =AF26/AF24 -> #DIV/0! | AG28: =AG26/AG24 -> #DIV/0! | AH28: =AH26/AH24 -> #DIV/0! | AI28: =AI26/AI24 -> #DIV/0! | ... AR28: =AR26/AR24 -> #DIV/0! | AS28: =AS25/AS24 -> #DIV/0! | AT28: =AT25/AT24 -> #DIV/0! | AU28: =AU25/AU24 -> #DIV/0! | AV28: =AV25/AV24 -> #DIV/0! | AW28: =AW25/AW24 -> #DIV/0! | AX28: =AX25/AX24 -> #DIV/0! | AY28: =AY25/AY24 -> #DIV/0! | AZ28: =AZ25/AZ24 -> #DIV/0! | ... EY28: =EY25/EY24 -> #DIV/0!
A30: Canada Total Reporting to Mir | B30: Canada Mir Total | C30: Canada | D30: Budget | BT30: =BT2+BT9+BT16 -> 0 | BU30: =BU2+BU9+BU16 -> 0 | BV30: =BV2+BV9+BV16 -> 0 | BW30: =BW2+BW9+BW16 -> 0 | BX30: =BX2+BX9+BX16 -> 0 | BY30: =BY2+BY9+BY16 -> 0 | BZ30: =BZ2+BZ9+BZ16 -> 0 | CA30: =CA2+CA9+CA16 -> 0 | ... EY30: =EY2+EY9+EY16 -> 0
D31: Forecast | BT31: =BT3+BT10+BT17 -> 33 | BU31: =BU3+BU10+BU17 -> 30 | BV31: =BV3+BV10+BV17 -> 32 | BW31: =BW3+BW10+BW17 -> 32 | BX31: =BX3+BX10+BX17 -> 19 | BY31: =BY3+BY10+BY17 -> 10 | BZ31: =BZ3+BZ10+BZ17 -> 10 | CA31: =CA3+CA10+CA17 -> 10 | ... DD31: =DD3+DD10+DD17 -> 32 | DE31: =DE3+DE10+DE17+DE24 -> 46.5 | DF31: =DF3+DF10+DF17+DF24 -> 46.5 | DG31: =DG3+DG10+DG17+DG24 -> 46.5 | DH31: =DH3+DH10+DH17+DH24 -> 46.5 | DI31: =DI3+DI10+DI17+DI24 -> 58.5 | DJ31: =DJ3+DJ10+DJ17+DJ24 -> 58.5 | DK31: =DK3+DK10+DK17+DK24 -> 58.5 | DL31: =DL3+DL10+DL17+DL24 -> 71.5 | ... DT31: =DT3+DT10+DT17+DT24 -> 70.5 | DU31: =DU3+DU10+DU17 -> 56 | DV31: =DV3+DV10+DV17 -> 55 | DW31: =DW3+DW10+DW17 -> 55 | DX31: =DX3+DX10+DX17 -> 55 | DY31: =DY3+DY10+DY17 -> 53 | DZ31: =DZ3+DZ10+DZ17 -> 45 | EA31: =EA3+EA10+EA17 -> 45 | EB31: =EB3+EB10+EB17 -> 45 | ... EY31: =EY3+EY10+EY17 -> 32
D32: Required | BT32: =BT4+BT11+BT18 -> 30 | BU32: =BU4+BU11+BU18 -> 25 | BV32: =BV4+BV11+BV18 -> 23 | BW32: =BW4+BW11+BW18 -> 22 | BX32: =BX4+BX11+BX18 -> 23.4 | BY32: =BY4+BY11+BY18 -> 15 | BZ32: =BZ4+BZ11+BZ18 -> 14 | CA32: =CA4+CA11+CA18 -> 14 | ... DD32: =DD4+DD11+DD18 -> 32 | DE32: =DE4+DE11+DE18+DE25 -> 55 | DF32: =DF4+DF11+DF18+DF25 -> 53 | DG32: =DG4+DG11+DG18+DG25 -> 53 | DH32: =DH4+DH11+DH18+DH25 -> 50 | DI32: =DI4+DI11+DI18+DI25 -> 66 | DJ32: =DJ4+DJ11+DJ18+DJ25 -> 68 | DK32: =DK4+DK11+DK18+DK25 -> 57 | DL32: =DL4+DL11+DL18+DL25 -> 78 | ... DT32: =DT4+DT11+DT18+DT25 -> 75.175 | DU32: =DU4+DU11+DU18 -> 58.175 | DV32: =DV4+DV11+DV18 -> 65.175 | DW32: =DW4+DW11+DW18 -> 65.129 | DX32: =DX4+DX11+DX18 -> 67.129 | DY32: =DY4+DY11+DY18 -> 63.301 | DZ32: =DZ4+DZ11+DZ18 -> 50.3955 | EA32: =EA4+EA11+EA18 -> 50.3955 | EB32: =EB4+EB11+EB18 -> 57.3955 | ... EY32: =EY4+EY11+EY18 -> 29.797985
D33: Projected | BT33: =BT5+BT12+BT19 -> 31 | BU33: =BU5+BU12+BU19 -> 28 | BV33: =BV5+BV12+BV19 -> 26 | BW33: =BW5+BW12+BW19 -> 25 | BX33: =BX5+BX12+BX19 -> 25.89 | BY33: =BY5+BY12+BY19 -> 8.89 | BZ33: =BZ5+BZ12+BZ19 -> 11.336975 | CA33: =CA5+CA12+CA19 -> 11.336975 | ... DD33: =DD5+DD12+DD19 -> 32 | DE33: =DE5+DE12+DE19+DE26 -> 55 | DF33: =DF5+DF12+DF19+DF26 -> 53 | DG33: =DG5+DG12+DG19+DG26 -> 53 | DH33: =DH5+DH12+DH19+DH26 -> 50 | DI33: =DI5+DI12+DI19+DI26 -> 66 | DJ33: =DJ5+DJ12+DJ19+DJ26 -> 68 | DK33: =DK5+DK12+DK19+DK26 -> 57 | DL33: =DL5+DL12+DL19+DL26 -> 78 | ... DT33: =DT5+DT12+DT19+DT26 -> 75.175 | DU33: =DU5+DU12+DU19 -> 58.175 | DV33: =DV5+DV12+DV19 -> 65.175 | DW33: =DW5+DW12+DW19 -> 65.129 | DX33: =DX5+DX12+DX19 -> 67.129 | DY33: =DY5+DY12+DY19 -> 63.301 | DZ33: =DZ5+DZ12+DZ19 -> 50.3955 | EA33: =EA5+EA12+EA19 -> 50.3955 | EB33: =EB5+EB12+EB19 -> 57.3955 | ... EY33: =EY5+EY12+EY19 -> 29.797985
D34: Budget Vs Actual | E34: =E32/E30 -> #DIV/0! | F34: =F32/F30 -> #DIV/0! | G34: =G32/G30 -> #DIV/0! | H34: =H32/H30 -> #DIV/0! | I34: =I32/I30 -> #DIV/0! | J34: =J32/J30 -> #DIV/0! | K34: =K32/K30 -> #DIV/0! | L34: =L32/L30 -> #DIV/0! | ... EY34: =EY32/EY30 -> #DIV/0!
D35: Forecast Vs Actual | E35: =E32/E31 -> #DIV/0! | F35: =F32/F31 -> #DIV/0! | G35: =G32/G31 -> #DIV/0! | H35: =H32/H31 -> #DIV/0! | I35: =I32/I31 -> #DIV/0! | J35: =J32/J31 -> #DIV/0! | K35: =K32/K31 -> #DIV/0! | L35: =L32/L31 -> #DIV/0! | ... AA35: =AA32/AA31 -> #DIV/0! | AB35: =AB33/AB31 -> #DIV/0! | AC35: =AC33/AC31 -> #DIV/0! | AD35: =AD33/AD31 -> #DIV/0! | AE35: =AE33/AE31 -> #DIV/0! | AF35: =AF33/AF31 -> #DIV/0! | AG35: =AG33/AG31 -> #DIV/0! | AH35: =AH33/AH31 -> #DIV/0! | AI35: =AI33/AI31 -> #DIV/0! | ... AR35: =AR33/AR31 -> #DIV/0! | AS35: =AS32/AS31 -> #DIV/0! | AT35: =AT32/AT31 -> #DIV/0! | AU35: =AU32/AU31 -> #DIV/0! | AV35: =AV32/AV31 -> #DIV/0! | AW35: =AW32/AW31 -> #DIV/0! | AX35: =AX32/AX31 -> #DIV/0! | AY35: =AY32/AY31 -> #DIV/0! | AZ35: =AZ32/AZ31 -> #DIV/0! | ... EY35: =EY32/EY31 -> 0.93118703

Sheet US
A1: H2R Department | B1: Client Name | C1: Country | E1: 45340 | F1: =E1+7 -> 45347 | G1: =F1+7 -> 45354 | H1: =G1+7 -> 45361 | I1: =H1+7 -> 45368 | J1: =I1+7 -> 45375 | K1: =J1+7 -> 45382 | L1: =K1+7 -> 45389 | M1: =L1+7 -> 45396 | ... EY1: =EX1+7 -> 46390
A2: DoorDash USA | B2: DoorDash USA | C2: USA | D2: Budget | E2: 100 | F2: 100 | G2: 100 | H2: 100 | I2: 100 | J2: 100 | K2: 100 | L2: 100 | M2: 100 | N2: 100 | O2: 100 | P2: 100 | Q2: 100 | R2: 100 | S2: 100 | T2: 100 | U2: 100 | V2: 100 | W2: 100 | X2: 100 | Y2: 100 | Z2: 100 | AA2: 100 | AB2: 100 | AC2: 100 | AD2: 100 | AE2: 100 | AF2: 100 | AG2: 100 | AH2: 100 | AI2: 100 | AJ2: 100 | AK2: 100 | AL2: 100 | AM2: 100 | AN2: 100 | AO2: 100 | AP2: 100 | AQ2: 100 | AR2: 100 | AS2: 100 | AT2: 100 | AU2: 100 | AV2: 100 | AW2: 100
D3: Forecast | E3: 71 | F3: 71 | G3: 81 | H3: 71 | I3: 64 | J3: 73 | K3: 71 | L3: 63 | M3: 68 | N3: 66 | O3: 51 | P3: 55 | Q3: 57 | R3: 59 | S3: 53 | T3: 69 | U3: 71 | V3: 70 | W3: 76 | X3: 75 | Y3: 78 | Z3: 83 | AA3: 86 | AB3: 103 | AC3: 101 | AD3: 95 | AE3: 90 | AF3: 90 | AG3: 101 | AH3: 95 | AI3: 82 | AJ3: 83 | AK3: 72 | AL3: 68 | AM3: 51 | AN3: 44 | AO3: 48 | AP3: 44 | AQ3: 48 | AR3: 44 | AS3: 38 | AT3: 34 | AU3: 34 | AV3: 34 | AW3: 35 | AX3: 44 | AY3: 40 | AZ3: 40 | BA3: 40 | BB3: 40 | BC3: 40 | BD3: 40 | BE3: 40 | BF3: 40 | BG3: 40 | BH3: 38 | BI3: 38 | BJ3: 50 | BK3: 50 | BL3: 50 | BM3: 50 | BN3: 50 | BO3: 48 | BP3: 48 | BQ3: 48 | BR3: 47 | BS3: 47 | BT3: 47 | BU3: 45 | BV3: 45 | BW3: 45 | BX3: 19
D4: Required | E4: 70.835983 | F4: 62.79435 | G4: 69.44535 | H4: 62.265176 | I4: 70.552 | J4: 75.496585 | K4: 67.596578 | L4: 64.269654 | M4: 68.73911 | N4: 60.861294 | O4: 48.10826 | P4: 49.58826 | Q4: 61.51326 | R4: 71.56826 | S4: 63.37326 | T4: 73.10726 | U4: 62.83726 | V4: 72.92726 | W4: 75 | X4: 86 | Y4: 91 | Z4: 97 | AA4: 96 | AB4: 112 | AC4: 102 | AD4: 95 | AE4: 94 | AF4: 89 | AG4: 100 | AH4: 103 | AI4: 103 | AJ4: 101 | AK4: 101 | AL4: 96 | AM4: 66 | AN4: 63 | AO4: 46 | AP4: 45 | AQ4: 52 | AR4: 46 | AS4: 48 | AT4: 47 | AU4: 47 | AV4: 46 | AW4: 44 | AX4: 44 | AY4: 33 | AZ4: 41 | BA4: 40 | BB4: 39 | BC4: 32 | BD4: 44 | BE4: 41 | BF4: 42 | BG4: 32 | BH4: 42 | BI4: 42 | BJ4: 48 | BK4: 48 | BL4: 48 | BM4: 44 | BN4: 48 | BO4: 48 | BP4: 46 | BQ4: 44 | BR4: 44 | BS4: 42 | BT4: 42 | BU4: 45 | BV4: 42 | BW4: 38 | BX4: 20
D5: Projected | AA5: 110 | AB5: 139 | AC5: 124 | AD5: 116 | AE5: 111 | AF5: 108 | AG5: 115 | AH5: 119 | AI5: 117 | AJ5: 116 | AK5: 116 | AL5: 110 | AM5: 91 | AN5: 88 | AO5: 69 | AP5: 68 | AQ5: 69 | AR5: 67 | AS5: 68 | AT5: 67 | AU5: 66 | AV5: 65 | AW5: 62 | AX5: 62 | AY5: 62 | AZ5: 59 | BA5: 57 | BB5: 57 | BC5: 57 | BD5: 57 | BE5: 57 | BF5: 57 | BG5: 57 | BH5: 57 | BI5: 57 | BJ5: 56 | BK5: 56 | BL5: 56 | BM5: 55 | BN5: 55 | BO5: 55 | BP5: 53 | BQ5: 49 | BR5: 49 | BS5: 47 | BT5: 47 | BU5: 46 | BV5: 46 | BW5: 42 | BX5: 21
D6: Budget Vs Actual | E6: =E4/E2 -> 0.70835983 | F6: =F4/F2 -> 0.6279435 | G6: =G4/G2 -> 0.6944535 | H6: =H4/H2 -> 0.62265176 | I6: =I4/I2 -> 0.70552 | J6: =J4/J2 -> 0.75496585 | K6: =K4/K2 -> 0.67596578 | L6: =L4/L2 -> 0.64269654 | ... EY6: =EY4/EY2 -> #DIV/0!
D7: Forecast Vs Actual | E7: =E4/E3 -> 0.9976899 | F7: =F4/F3 -> 0.88442746 | G7: =G4/G3 -> 0.85735 | H7: =H4/H3 -> 0.87697431 | I7: =I4/I3 -> 1.102375 | J7: =J4/J3 -> 1.0341998 | K7: =K4/K3 -> 0.95206448 | L7: =L4/L3 -> 1.0201532 | ... AA7: =AA4/AA3 -> 1.1162791 | AB7: =AB5/AB3 -> 1.3495146 | AC7: =AC5/AC3 -> 1.2277228 | AD7: =AD5/AD3 -> 1.2210526 | AE7: =AE5/AE3 -> 1.2333333 | AF7: =AF5/AF3 -> 1.2 | AG7: =AG5/AG3 -> 1.1386139 | AH7: =AH5/AH3 -> 1.2526316 | AI7: =AI5/AI3 -> 1.4268293 | ... AR7: =AR5/AR3 -> 1.5227273 | AS7: =AS4/AS3 -> 1.2631579 | AT7: =AT4/AT3 -> 1.3823529 | AU7: =AU4/AU3 -> 1.3823529 | AV7: =AV4/AV3 -> 1.3529412 | AW7: =AW4/AW3 -> 1.2571429 | AX7: =AX4/AX3 -> 1 | AY7: =AY4/AY3 -> 0.825 | AZ7: =AZ4/AZ3 -> 1.025 | ... EY7: =EY4/EY3 -> #DIV/0!
A9: Entergy Services LLC | B9: Entergy | C9: USA | D9: Budget | E9: 148.62017 | F9: 148.62017 | G9: 150.07782 | H9: 150.07782 | I9: 150.07782 | J9: 150.07782 | K9: 141.20222 | L9: 141.20222 | M9: 141.20222 | N9: 141.20222 | O9: 146.46971 | P9: 146.46971 | Q9: 146.46971 | R9: 146.46971 | S9: 171.39215 | T9: 171.39215 | U9: 171.39215 | V9: 171.39215 | W9: 171.39215 | X9: 167.16921 | Y9: 167.16921 | Z9: 167.16921 | AA9: 167.16921 | AB9: 186.05511 | AC9: 186.05511 | AD9: 186.05511 | AE9: 186.05511 | AF9: 186.05511 | AG9: 168.11119 | AH9: 168.11119 | AI9: 168.11119 | AJ9: 168.11119 | AK9: 140.37348 | AL9: 140.37348 | AM9: 140.37348 | AN9: 140.37348 | AO9: 140.3354 | AP9: 140.3354 | AQ9: 140.3354 | AR9: 140.3354 | AS9: 140.3354 | AT9: 131.8103 | AU9: 131.8103 | AV9: 131.8103 | AW9: 131.8103
D10: Forecast | E10: 166.53242 | F10: 190.04197 | G10: 235.65279 | H10: 222.94446 | I10: 220.07848 | J10: 218.1553 | K10: 179.11024 | L10: 160.01033 | M10: 147.43822 | N10: 141.29028 | O10: 151.69676 | P10: 165.12525 | Q10: 153.92525 | R10: 155.01542 | S10: 170.4723 | T10: 183.41746 | U10: 171.70992 | V10: 181.82435 | W10: 178.35257 | X10: 172.2771 | Y10: 168.48264 | Z10: 149.89957 | AA10: 154.71297 | AB10: 106.08259 | AC10: 119.30524 | AD10: 114.35479 | AE10: 111.54679 | AF10: 108.52278 | AG10: 97.737106 | AH10: 104.24141 | AI10: 89.720724 | AJ10: 98.321841 | AK10: 100.66396 | AL10: 92.124344 | AM10: 98.95744 | AN10: 105.07855 | AO10: 100.91156 | AP10: 90.606395 | AQ10: 91.721449 | AR10: 96.161524 | AS10: 76.243955 | AT10: 110.34279 | AU10: 103.10258 | AV10: 98.846552 | AW10: 65.552247 | AX10: 88.987826 | AY10: 109.56522 | AZ10: 106.66667 | BA10: 85.333333 | BB10: 106.66667 | BC10: 112 | BD10: 110.22222 | BE10: 104.88889 | BF10: 113.77778 | BG10: 110.22222 | BH10: 108.44444 | BI10: 99.555556 | BJ10: 115.55556 | BK10: 107.29412 | BL10: 109.17647 | BM10: 99.764706 | BN10: 97.882353 | BO10: 105.41176 | BP10: 111.05882 | BQ10: 105.41176 | BR10: 105.41176 | BS10: 96.376471 | BT10: 120.47059 | BU10: 114.82353 | BV10: 107.29412 | BW10: 109.17647 | BX10: 97.882353 | BY10: 118.58824 | BZ10: 105.41176 | CA10: 107.29412 | CB10: 107.82609 | CC10: 116.52174 | CD10: 109.56522 | CE10: 111.05882 | CF10: 112.94118 | CG10: 79.811765 | CH10: 92.235294 | CI10: 82.758621 | CJ10: 84.597701 | CK10: 86.436782 | CL10: 79.08046 | CM10: 72.727273 | CN10: 72.727273 | CO10: 76.363636 | CP10: 83.636364 | CQ10: 80 | CR10: 76.363636 | CS10: 50.909091 | CT10: 80 | CU10: 72.727273 | CV10: 65.454545 | CW10: 32 | CX10: 56.727273 | CY10: 96.363636 | CZ10: 89.090909 | DA10: 66.909091 | DB10: 90.909091 | DC10: 89.090909 | DD10: 81.818182 | DE10: 83.636364 | DF10: 85.454545 | DG10: 92.727273 | DH10: 89.090909 | DI10: 83.636364 | DJ10: 83.636364 | DK10: 96.363636 | DL10: 90.909091 | DM10: 83.636364 | DN10: 84.705882 | DO10: 94.117647 | DP10: 93.913043 | DQ10: 94.117647 | DR10: 92.235294 | DS10: 76.8 | DT10: 101.64706 | DU10: 94.117647 | DV10: 92.235294 | DW10: 89.090909 | DX10: 82.909091 | DY10: 98.181818 | DZ10: 90.909091 | EA10: 90.909091 | EB10: 96.363636 | EC10: 101.81818 | ED10: 90.909091 | EE10: 90.909091 | EF10: 92.727273 | EG10: 100 | EH10: 77.090909 | EI10: 89.090909 | EJ10: 89.090909 | EK10: 96.363636 | EL10: 89.090909 | EM10: 83.636364 | EN10: 83.636364 | EO10: 85.454545 | EP10: 81.818182 | EQ10: 76.363636 | ER10: 72.727273 | ES10: 46.545455 | ET10: 80 | EU10: 67.272727 | EV10: 60 | EW10: 30.909091 | EX10: 87.272727 | EY10: 87.272727
D11: Required | AB11: 150.63201 | AC11: 163.63357 | AD11: 156.84377 | AE11: 152.99245 | AF11: 148.84486 | AG11: 135.85164 | AH11: 144.89243 | AI11: 122.94822 | AJ11: 133.05723 | AK11: 136.3456 | AL11: 127.96825 | AM11: 117.70559 | AN11: 124.98638 | AO11: 119.144 | AP11: 109.60072 | AQ11: 110.40136 | AR11: 115.7457 | AS11: 91.771732 | AT11: 115.17841 | AU11: 110.31144 | AV11: 105.75783 | AW11: 68.424984 | AX11: 86.385464 | AY11: 130.82414 | AZ11: 127.36318 | BA11: 99.514091 | BB11: 125.86037 | BC11: 132.15339 | BD11: 130.82756 | BE11: 124.4972 | BF11: 133.46367 | BG11: 129.29293 | BH11: 127.5817 | BI11: 117.81723 | BJ11: 140.06734 | BK11: 132.3475 | BL11: 134.37104 | BM11: 122.56106 | BN11: 118.68844 | BO11: 128.91252 | BP11: 134.66573 | BQ11: 129.96149 | BR11: 139.15745 | BS11: 117.53586 | BT11: 148.12337 | BU11: 141.18009 | BV11: 123.86045 | BW11: 127.75902 | BX11: 112.9955 | BY11: 136.8984 | BZ11: 122.02643 | CA11: 128.20135 | CB11: 124.82129 | CC11: 138.8548 | CD11: 126.83453 | CE11: 129.64696 | CF11: 131.1078 | CG11: 91.625761 | CH11: 105.88826 | CI11: 93.714422 | CJ11: 95.796965 | CK11: 97.879508 | CL11: 88.345717 | CM11: 81.687354 | CN11: 81.687354 | CO11: 85.310584 | CP11: 93.435401 | CQ11: 89.372993 | CR11: 85.310584 | CS11: 56.873723 | CT11: 89.372993 | CU11: 81.248175 | CV11: 73.918177 | CW11: 36.137775 | CX11: 64.06242 | CY11: 108.82398 | CZ11: 100.61085 | DA11: 77.67144 | DB11: 105.53185 | DC11: 103.42121 | DD11: 94.978663 | DE11: 97.0893 | DF11: 98.923614 | DG11: 107.34264 | DH11: 103.13313 | DI11: 96.818856 | DJ11: 96.818856 | DK11: 111.55216 | DL11: 105.23789 | DM11: 96.818856 | DN11: 98.056949 | DO11: 108.95217 | DP11: 108.71531 | DQ11: 108.95217 | DR11: 107.54108 | DS11: 89.544408 | DT11: 117.22645 | DU11: 108.54301 | DV11: 106.37215 | DW11: 102.74583 | DX11: 95.616527 | DY11: 113.2301 | DZ11: 103.74197 | EA11: 103.74197 | EB11: 109.39225 | EC11: 115.58427 | ED11: 104.33431 | EE11: 103.20024 | EF11: 105.26424 | EG11: 113.52026 | EH11: 87.513803 | EI11: 101.13623 | EJ11: 101.13623 | EK11: 109.39225 | EL11: 101.13623 | EM11: 94.94422 | EN11: 94.94422 | EO11: 97.008225 | EP11: 92.880215 | EQ11: 86.688201 | ER11: 82.560192 | ES11: 52.838523 | ET11: 90.816211 | EU11: 75.154562 | EV11: 67.029744 | EW11: 34.530474 | EX11: 97.49781 | EY11: 97.49781
D12: Projected | E12: 195 | F12: 195 | G12: 223 | H12: 214 | I12: 207 | J12: 197 | K12: 184 | L12: 174 | M12: 167 | N12: 163 | O12: 156 | P12: 171 | Q12: 165 | R12: 181 | S12: 176 | T12: 177 | U12: 176.34165 | V12: 171 | W12: 179.20443 | X12: 177.42242 | Y12: 171.14969 | Z12: 160.81403 | AA12: 154.15999 | AB12: 172.04 | AC12: 162.88 | AD12: 155.88 | AE12: 148.88 | AF12: 138.88 | AG12: 132.88 | AH12: 138.88 | AI12: 126.88 | AJ12: 137.88 | AK12: 138.88 | AL12: 127.88 | AM12: 124.88 | AN12: 125.88 | AO12: 127.872 | AP12: 114.88 | AQ12: 125.88 | AR12: 120.88 | AS12: 119.88 | AT12: 126.88 | AU12: 122.88 | AV12: 119.88 | AW12: 105.88 | AX12: 132.55 | AY12: 130.88 | AZ12: 126.88 | BA12: 114.88 | BB12: 118.88 | BC12: 114.88 | BD12: 111.88 | BE12: 127.88 | BF12: 121.88 | BG12: 137.88 | BH12: 125.88 | BI12: 119.88 | BJ12: 144.88 | BK12: 139.88 | BL12: 133.88 | BM12: 130.88 | BN12: 131.88 | BO12: 137.88 | BP12: 131.88 | BQ12: 140.88 | BR12: 135.88 | BS12: 151.88 | BT12: 136.88 | BU12: 140.88 | BV12: 133.88 | BW12: 140.88 | BX12: 136.88 | BY12: 132.88 | BZ12: 123.88 | CA12: 130.88 | CB12: 125.88 | CC12: 136.88 | CD12: 130.92 | CE12: 133.88 | CF12: 132.88 | CG12: 128.88 | CH12: 124.88 | CI12: 126.88 | CJ12: 125 | CK12: 121.88 | CL12: 119.88 | CM12: 116.88 | CN12: 113.88 | CO12: 112.88 | CP12: 111.88 | CQ12: 109.88 | CR12: 105.88 | CS12: 104.88 | CT12: 109.88 | CU12: 105.88 | CV12: 104.88 | CW12: 101.88 | CX12: 100.88 | CY12: 101.88 | CZ12: 98.413333 | DA12: 89.88 | DB12: 88.88 | DC12: 104.88 | DD12: 104.88 | DE12: 99.88 | DF12: 95.88 | DG12: 105.88 | DH12: 102.88 | DI12: 100.88 | DJ12: 99.88 | DK12: 101.88 | DL12: 94.88 | DM12: 93.88 | DN12: 110.88 | DO12: 109.88 | DP12: 110.88 | DQ12: 109.88 | DR12: 119.88 | DS12: 118.88 | DT12: 118.88 | DU12: 126.88 | DV12: 123.88 | DW12: 118.88 | DX12: 117.88 | DY12: 127.88 | DZ12: 124.88 | EA12: 120.88 | EB12: 117.88 | EC12: 115.88 | ED12: 113.88 | EE12: 111.88 | EF12: 109.88 | EG12: 107.88 | EH12: 105.88 | EI12: 103.88 | EJ12: 101.88 | EK12: 106.46096 | EL12: 103.80286 | EM12: 101.80286 | EN12: 99.802864 | EO12: 97.802864 | EP12: 95.802864 | EQ12: 93.802864 | ER12: 91.802864 | ES12: 89.802864 | ET12: 87.802864 | EU12: 66.965906 | EV12: 64.965906 | EW12: 62.965906 | EX12: 97.88 | EY12: 97.88
D13: Budget Vs Actual | E13: =E12/E9 -> 1.3120695 | F13: =F12/F9 -> 1.3120695 | G13: =G12/G9 -> 1.4858958 | H13: =H12/H9 -> 1.4259269 | I13: =I12/I9 -> 1.3792844 | J13: =J12/J9 -> 1.3126523 | K13: =K12/K9 -> 1.3030956 | L13: =L12/L9 -> 1.2322752 | ... EY13: =EY12/EY9 -> #DIV/0!
D14: Forecast Vs Actual | E14: =E12/E10 -> 1.1709431 | F14: =F12/F10 -> 1.0260891 | G14: =G12/G10 -> 0.9463075 | H14: =H12/H10 -> 0.95988033 | I14: =I12/I10 -> 0.94057356 | J14: =J12/J10 -> 0.90302642 | K14: =K12/K10 -> 1.0273003 | L14: =L12/L10 -> 1.0874298 | ... BU14: =BU12/BU10 -> 1.2269262 | BV14: =BV11/BV10 -> 1.1544012 | BW14: =BW11/BW10 -> 1.1702065 | BX14: =BX11/BX10 -> 1.1544012 | BY14: =BY11/BY10 -> 1.1544012 | BZ14: =BZ11/BZ10 -> 1.1576168 | CA14: =CA11/CA10 -> 1.1948591 | CB14: =CB11/CB10 -> 1.1576168 | CC14: =CC11/CC10 -> 1.1916643 | ... CK14: =CK11/CK10 -> 1.1323826 | CL14: =CL12/CL10 -> 1.5159244 | CM14: =CM12/CM10 -> 1.6071 | CN14: =CN12/CN10 -> 1.56585 | CO14: =CO12/CO10 -> 1.4781905 | CP14: =CP12/CP10 -> 1.3376957 | CQ14: =CQ12/CQ10 -> 1.3735 | CR14: =CR12/CR10 -> 1.3865238 | CS14: =CS12/CS10 -> 2.0601429 | ... EY14: =EY12/EY10 -> 1.1215417
A16: PNMR SERVICES COMPANY | B16: PNM | C16: USA | D16: Budget | E16: 15 | F16: 15 | G16: 15 | H16: 15 | I16: 15 | J16: 15 | K16: 15 | L16: 15 | M16: 15 | N16: 15 | O16: 15 | P16: 15 | Q16: 15 | R16: 15 | S16: 15 | T16: 15 | U16: 15 | V16: 15 | W16: 15 | X16: 15 | Y16: 15 | Z16: 15 | AA16: 15 | AB16: 15 | AC16: 15 | AD16: 15 | AE16: 15 | AF16: 15 | AG16: 15 | AH16: 15 | AI16: 15 | AJ16: 15 | AK16: 15 | AL16: 15 | AM16: 15 | AN16: 15 | AO16: 15 | AP16: 15 | AQ16: 15 | AR16: 15 | AS16: 15 | AT16: 15 | AU16: 15 | AV16: 15 | AW16: 15
D17: Forecast | E17: 14 | F17: 14 | G17: 14 | H17: 14 | I17: 14 | J17: 14 | K17: 14 | L17: 14 | M17: 14 | N17: 14 | O17: 14 | P17: 14 | Q17: 14 | R17: 14 | S17: 14 | T17: 11 | U17: 11 | V17: 11 | W17: 10 | X17: 10 | Y17: 10 | Z17: 10 | AA17: 10 | AB17: 10 | AC17: 10 | AD17: 10 | AE17: 10 | AF17: 10 | AG17: 10 | AH17: 10 | AI17: 10 | AJ17: 10 | AK17: 10 | AL17: 10 | AM17: 10 | AN17: 10 | AO17: 10 | AP17: 10 | AQ17: 9 | AR17: 9 | AS17: 8 | AT17: 8 | AU17: 9 | AV17: 9 | AW17: 9 | AX17: 9 | AY17: 9 | AZ17: 8 | BA17: 8 | BB17: 9 | BC17: 9 | BD17: 9 | BE17: 9 | BF17: 9 | BG17: 9 | BH17: 9 | BI17: 9 | BJ17: 9 | BK17: 9 | BL17: 9 | BM17: 7 | BN17: 17 | BO17: 16 | BP17: 16 | BQ17: 16 | BR17: 16 | BS17: 16 | BT17: 16 | BU17: 16 | BV17: 16 | BW17: 16 | BX17: 15 | BY17: 15 | BZ17: 15 | CA17: 15 | CB17: 15 | CC17: 14 | CD17: 14 | CE17: 13 | CF17: 13 | CG17: 12 | CH17: 13 | CI17: 12 | CJ17: 12 | CK17: 11 | CL17: 11 | CM17: 11 | CN17: 10 | CO17: 10 | CP17: 10 | CQ17: 10 | CR17: 10 | CS17: 10 | CT17: 10 | CU17: 10 | CV17: 10 | CW17: 10 | CX17: 10 | CY17: 10 | CZ17: 10 | DA17: 10 | DB17: 10 | DC17: 10 | DD17: 10 | DE17: 10 | DF17: 10 | DG17: 10 | DH17: 10 | DI17: 10 | DJ17: 10 | DK17: 10 | DL17: 10 | DM17: 10 | DN17: 10 | DO17: 10 | DP17: 10 | DQ17: 10 | DR17: 10 | DS17: 10 | DT17: 10 | DU17: 10 | DV17: 10 | DW17: 10 | DX17: 9 | DY17: 9 | DZ17: 9 | EA17: 9 | EB17: 9 | EC17: 9 | ED17: 8 | EE17: 9 | EF17: 9 | EG17: 9 | EH17: 9 | EI17: 8 | EJ17: 8 | EK17: 8 | EL17: 8 | EM17: 7 | EN17: 7 | EO17: 7 | EP17: 7 | EQ17: 6 | ER17: 6 | ES17: 6 | ET17: 6 | EU17: 11 | EV17: 11 | EW17: 11 | EX17: 11 | EY17: 11
D18: Required | AB18: 10 | AC18: 10 | AD18: 10 | AE18: 10 | AF18: 10 | AG18: 10 | AH18: 10 | AI18: 10 | AJ18: 10 | AK18: 10 | AL18: 10 | AM18: 10 | AN18: 10 | AO18: 10 | AP18: 10 | AQ18: 9 | AR18: 9 | AS18: 8 | AT18: 8 | AU18: 9 | AV18: 9 | AW18: 9 | AX18: 9 | AY18: 9 | AZ18: 8 | BA18: 8 | BB18: 9 | BC18: 9 | BD18: 9 | BE18: 9 | BF18: 9 | BG18: 9 | BH18: 9 | BI18: 9 | BJ18: 9 | BK18: 9 | BL18: 9 | BM18: 7 | BN18: 17 | BO18: 16 | BP18: 16 | BQ18: 16 | BR18: 16 | BS18: 16 | BT18: 16 | BU18: 16 | BV18: 16 | BW18: 16 | BX18: 15 | BY18: 15 | BZ18: 15 | CA18: 15 | CB18: 15 | CC18: 14 | CD18: 14 | CE18: 13 | CF18: 13 | CG18: 12 | CH18: 13 | CI18: 12 | CJ18: 12 | CK18: 11 | CL18: 11 | CM18: 11 | CN18: 10 | CO18: 10 | CP18: 10 | CQ18: 10 | CR18: 10 | CS18: 10 | CT18: 10 | CU18: 10 | CV18: 10 | CW18: 10 | CX18: 10 | CY18: 10 | CZ18: 10 | DA18: 10 | DB18: 10 | DC18: 10 | DD18: 10 | DE18: 10 | DF18: 10 | DG18: 10 | DH18: 10 | DI18: 10 | DJ18: 10 | DK18: 10 | DL18: 10 | DM18: 10 | DN18: 10 | DO18: 10 | DP18: 10 | DQ18: 10 | DR18: 10 | DS18: 10 | DT18: 10 | DU18: 10 | DV18: 10 | DW18: 10 | DX18: 9 | DY18: 9 | DZ18: 9 | EA18: 9 | EB18: 9 | EC18: 9 | ED18: 8 | EE18: 9 | EF18: 9 | EG18: 9 | EH18: 9 | EI18: 8 | EJ18: 8 | EK18: 8 | EL18: 8 | EM18: 7 | EN18: 7 | EO18: 7 | EP18: 7 | EQ18: 6 | ER18: 6 | ES18: 6 | ET18: 6 | EU18: 11 | EV18: 11 | EW18: 11 | EX18: 11 | EY18: 11
D19: Projected | E19: 12 | F19: 12 | G19: 12 | H19: 12 | I19: 12 | J19: 12 | K19: 12 | L19: 12 | M19: 11 | N19: 11 | O19: 11 | P19: 11 | Q19: 11 | R19: 11 | S19: 11 | T19: 11 | U19: 11 | V19: 11 | W19: 10 | X19: 10 | Y19: 10 | Z19: 10 | AA19: 10 | AB19: 10 | AC19: =AC18 -> 10 | AD19: =AD18 -> 10 | AE19: =AE18 -> 10 | AF19: =AF18 -> 10 | AG19: =AG18 -> 10 | AH19: =AH18 -> 10 | AI19: =AI18 -> 10 | AJ19: =AJ18 -> 10 | ... EY19: =EY18 -> 11
D20: Budget Vs Actual | E20: =E19/E16 -> 0.8 | F20: =F19/F16 -> 0.8 | G20: =G19/G16 -> 0.8 | H20: =H19/H16 -> 0.8 | I20: =I19/I16 -> 0.8 | J20: =J19/J16 -> 0.8 | K20: =K19/K16 -> 0.8 | L20: =L19/L16 -> 0.8 | ... EY20: =EY19/EY16 -> #DIV/0!
D21: Forecast Vs Actual | E21: =E19/E17 -> 0.85714286 | F21: =F19/F17 -> 0.85714286 | G21: =G19/G17 -> 0.85714286 | H21: =H19/H17 -> 0.85714286 | I21: =I19/I17 -> 0.85714286 | J21: =J19/J17 -> 0.85714286 | K21: =K19/K17 -> 0.85714286 | L21: =L19/L17 -> 0.85714286 | ... EY21: =EY19/EY17 -> 1
A23: Liberty Utilities | B23: Liberty Utilities | C23: USA | D23: Budget | E23: 41 | F23: 41 | G23: 41 | H23: 41 | I23: 41 | J23: 41 | K23: 41 | L23: 41 | M23: 41 | N23: 41 | O23: 41 | P23: 41 | Q23: 41 | R23: 41 | S23: 41 | T23: 41 | U23: 41 | V23: 41 | W23: 41
D24: Forecast | E24: 65 | F24: 65 | G24: 65 | H24: 65 | I24: 65 | J24: 65 | K24: 65 | L24: 65 | M24: 65 | N24: 65 | O24: 65 | P24: 65 | Q24: 65 | R24: 65 | S24: 65 | T24: 65 | U24: 61 | V24: 60 | W24: 60 | DA24: 0 | DB24: 0 | DC24: 0 | DD24: 0 | DE24: 10 | DF24: 10 | DG24: 10 | DH24: 10 | DI24: 10 | DJ24: 10 | DK24: 10 | DL24: 10 | DM24: 17.333333 | DN24: 22.431373 | DO24: 22.431373 | DP24: 24.470588 | DQ24: 30.588235 | DR24: 28.54902 | DS24: 39.152941 | DT24: 38.745098 | DU24: 38.745098 | DV24: 38.745098 | DW24: 46.901961 | DX24: 26.346667 | DY24: 34.666667 | DZ24: 34.666667 | EA24: 34.666667 | EB24: 34.666667 | EC24: 38.133333 | ED24: 38.133333 | EE24: 38.133333 | EF24: 38.133333 | EG24: 39.866667 | EH24: 39.866667 | EI24: 39.866667 | EJ24: 39.866667 | EK24: 39.866667 | EL24: 38.133333 | EM24: 38.133333 | EN24: 38.133333 | EO24: 38.133333 | EP24: 38.133333 | EQ24: 38.133333 | ER24: 38.133333 | ES24: 38.133333 | ET24: 38.133333
D25: Required | DA25: 0 | DB25: 0 | DC25: 0 | DD25: 0 | DE25: 9 | DF25: 10 | DG25: 9 | DH25: 10 | DI25: 10 | DJ25: 8 | DK25: 8 | DL25: 8 | DM25: 19.914444 | DN25: 25.771634 | DO25: 25.367682 | DP25: 28.302785 | DQ25: 38.475768 | DR25: 32.107764 | DS25: 44.033505 | DT25: 42.864363 | DU25: 42.864363 | DV25: 43.083618 | DW25: 53.018282 | DX25: 31.199342 | DY25: 39.991679 | DZ25: 39.847888 | EA25: 39.847888 | EB25: 39.847888 | EC25: 43.720859 | ED25: 43.720859 | EE25: 42.996204 | EF25: 42.996204 | EG25: 44.950577 | EH25: 44.950577 | EI25: 44.950577 | EJ25: 44.950577 | EK25: 44.950577 | EL25: 42.996204 | EM25: 42.996204 | EN25: 42.996204 | EO25: 42.996204 | EP25: 42.996204 | EQ25: 42.996204 | ER25: 42.996204 | ES25: 42.996204 | ET25: 42.996204
D26: Projected | E26: 80 | F26: 77 | G26: 72 | H26: 69 | I26: 68 | J26: 68 | K26: 66 | L26: 89 | M26: 88 | N26: 88 | O26: 87 | P26: 88 | Q26: 86 | R26: 84 | S26: 84 | T26: 68 | U26: 61 | V26: 59 | W26: 59 | DA26: =DA24 -> 0 | DB26: =DB24 -> 0 | DC26: =DC24 -> 0 | DD26: =DD24 -> 0 | DE26: =DE25 -> 9 | DF26: =DF25 -> 10 | DG26: =DG25 -> 9 | DH26: =DH25 -> 10 | DI26: =DI25 -> 10 | DJ26: =DJ25 -> 8 | DK26: =DK25 -> 8 | DL26: =DL25 -> 8 | ... ET26: =ET25 -> 42.996204
D27: Budget Vs Actual | E27: =E26/E23 -> 1.9512195 | F27: =F26/F23 -> 1.8780488 | G27: =G26/G23 -> 1.7560976 | H27: =H26/H23 -> 1.6829268 | I27: =I26/I23 -> 1.6585366 | J27: =J26/J23 -> 1.6585366 | K27: =K26/K23 -> 1.6097561 | L27: =L26/L23 -> 2.1707317 | ... EY27: =EY26/EY23 -> #DIV/0!
D28: Forecast Vs Actual | E28: =E26/E24 -> 1.2307692 | F28: =F26/F24 -> 1.1846154 | G28: =G26/G24 -> 1.1076923 | H28: =H26/H24 -> 1.0615385 | I28: =I26/I24 -> 1.0461538 | J28: =J26/J24 -> 1.0461538 | K28: =K26/K24 -> 1.0153846 | L28: =L26/L24 -> 1.3692308 | ... EY28: =EY26/EY24 -> #DIV/0!
A30: ExactScience | B30: ExactScience | C30: USA | D30: Budget
D31: Forecast | EF31: 15 | EG31: 15 | EH31: 15 | EI31: 15 | EJ31: 25 | EK31: 25 | EL31: 25 | EM31: 25 | EN31: 25 | EO31: 30 | EP31: 30 | EQ31: 50 | ER31: 50 | ES31: 50 | ET31: 50 | EU31: 70.805327 | EV31: 70.805327 | EW31: 70.805327 | EX31: 69.743247
D32: Required | EF32: 15 | EG32: 15 | EH32: 15 | EI32: 15 | EJ32: 25 | EK32: 25 | EL32: 25 | EM32: 25 | EN32: 25 | EO32: 30 | EP32: 30 | EQ32: 50 | ER32: 50 | ES32: 50 | ET32: 50 | EU32: 70 | EV32: 70 | EW32: 70 | EX32: 70
D33: Projected | EF33: 18.75 | EG33: 17.188125 | EH33: 17.188125 | EI33: 26.4006 | EJ33: 25.57593 | EK33: 24.57593 | EL33: 23.592893 | EM33: 23.592893 | EN33: 33.492893 | EO33: 32.314329 | EP33: 32.314329 | EQ33: 52.939329 | ER33: 48.736552 | ES33: 48.736552 | ET33: 48.736552 | EU33: 70.805327 | EV33: 70.805327 | EW33: 70.805327 | EX33: 69.743247 | EY33: =EY32 -> 0
D34: Budget Vs Actual | E34: =E33/E30 -> #DIV/0! | F34: =F33/F30 -> #DIV/0! | G34: =G33/G30 -> #DIV/0! | H34: =H33/H30 -> #DIV/0! | I34: =I33/I30 -> #DIV/0! | J34: =J33/J30 -> #DIV/0! | K34: =K33/K30 -> #DIV/0! | L34: =L33/L30 -> #DIV/0! | ... EY34: =EY33/EY30 -> #DIV/0!
D35: Forecast Vs Actual | E35: =E33/E31 -> #DIV/0! | F35: =F33/F31 -> #DIV/0! | G35: =G33/G31 -> #DIV/0! | H35: =H33/H31 -> #DIV/0! | I35: =I33/I31 -> #DIV/0! | J35: =J33/J31 -> #DIV/0! | K35: =K33/K31 -> #DIV/0! | L35: =L33/L31 -> #DIV/0! | ... EY35: =EY33/EY31 -> #DIV/0!
A37: HHCIP, LLC (CardioCare) | B37: Cardio Care | C37: USA | D37: Budget
D38: Forecast | BI38: 1 | BJ38: 1 | BK38: 2 | BL38: 2 | BM38: 2 | BN38: 2 | BO38: 2 | BP38: 2 | BQ38: 1 | BR38: 1 | BS38: 1 | BT38: 1 | BU38: 1 | BV38: 1 | BW38: 1 | BX38: 1 | BY38: 1 | BZ38: 1 | CA38: 1 | CB38: 1 | CC38: 1 | CD38: 1 | CE38: 1 | CF38: 1 | CG38: 1 | CH38: 1 | CI38: 1 | CJ38: 1 | CK38: 1 | CL38: 1 | CM38: 1 | CN38: 1 | CO38: 1 | CP38: 1 | CQ38: 1 | CR38: 0 | CS38: 0 | CT38: 0 | CU38: 0 | CV38: 0 | CW38: 0 | CX38: 0 | CY38: 0 | CZ38: 0 | DA38: 0 | DB38: 0 | DC38: 0 | DD38: 0 | DE38: 0 | DF38: 0 | DG38: 0 | DH38: 0 | DI38: 0 | DJ38: 0 | DK38: 0 | DL38: 0 | DM38: 0 | DN38: 0 | DO38: 0 | DP38: 0 | DQ38: 0 | DR38: 0 | DS38: 0 | DT38: 0 | DU38: 0 | DV38: 0 | DW38: 0 | DX38: 0 | DY38: 0 | DZ38: 0 | EA38: 0 | EB38: 0 | EC38: 0 | ED38: 0 | EE38: 0 | EF38: 0 | EG38: 0 | EH38: 0 | EI38: 0 | EJ38: 0 | EK38: 0 | EL38: 0 | EM38: 0 | EN38: 0 | EO38: 0 | EP38: 0 | EQ38: 0 | ER38: 0 | ES38: 0 | ET38: 0 | EU38: 0 | EV38: 0 | EW38: 0 | EX38: 0 | EY38: 0
D39: Required | BI39: 1 | BJ39: 1 | BK39: 2 | BL39: 2 | BM39: 2 | BN39: 2 | BO39: 2 | BP39: 2 | BQ39: 1 | BR39: 1 | BS39: 1 | BT39: 1 | BU39: 1 | BV39: 1 | BW39: 1 | BX39: 1 | BY39: 1 | BZ39: 1 | CA39: 1 | CB39: 1 | CC39: 1 | CD39: 1 | CE39: 1 | CF39: 1 | CG39: 1 | CH39: 1 | CI39: 1 | CJ39: 1 | CK39: 1 | CL39: 1 | CM39: 1 | CN39: 1 | CO39: 1 | CP39: 1 | CQ39: 1 | CR39: 0 | CS39: 0 | CT39: 0 | CU39: 0 | CV39: 0 | CW39: 0 | CX39: 0 | CY39: 0 | CZ39: 0 | DA39: 0 | DB39: 0 | DC39: 0 | DD39: 0 | DE39: 0 | DF39: 0 | DG39: 0 | DH39: 0 | DI39: 0 | DJ39: 0 | DK39: 0 | DL39: 0 | DM39: 0 | DN39: 0 | DO39: 0 | DP39: 0 | DQ39: 0 | DR39: 0 | DS39: 0 | DT39: 0 | DU39: 0 | DV39: 0 | DW39: 0 | DX39: 0 | DY39: 0 | DZ39: 0 | EA39: 0 | EB39: 0 | EC39: 0 | ED39: 0 | EE39: 0 | EF39: 0 | EG39: 0 | EH39: 0 | EI39: 0 | EJ39: 0 | EK39: 0 | EL39: 0 | EM39: 0 | EN39: 0 | EO39: 0 | EP39: 0 | EQ39: 0 | ER39: 0 | ES39: 0 | ET39: 0 | EU39: 0 | EV39: 0 | EW39: 0 | EX39: 0 | EY39: 0
D40: Projected | BI40: 1 | BJ40: 1 | BK40: 2 | BL40: 2 | BM40: 2 | BN40: 2 | BO40: 2 | BP40: 2 | BQ40: 1 | BR40: 1 | BS40: 1 | BT40: 1 | BU40: 1 | BV40: 1 | BW40: 1 | BX40: 1 | BY40: 1 | BZ40: 1 | CA40: 1 | CB40: 1 | CC40: 1 | CD40: 1 | CE40: 1 | CF40: 1 | CG40: 1 | CH40: 1 | CI40: 1 | CJ40: 1 | CK40: 1 | CL40: 1 | CM40: 1 | CN40: 1 | CO40: 1 | CP40: 1 | CQ40: 1 | CR40: 0 | CS40: 0 | CT40: 0 | CU40: 0 | CV40: 0 | CW40: 0 | CX40: 0 | CY40: 0 | CZ40: 0 | DA40: 0 | DB40: 0 | DC40: 0 | DD40: 0 | DE40: 0 | DF40: 0 | DG40: 0 | DH40: 0 | DI40: 0 | DJ40: 0 | DK40: 0 | DL40: 0 | DM40: 0 | DN40: 0 | DO40: 0 | DP40: 0 | DQ40: 0 | DR40: 0 | DS40: 0 | DT40: 0 | DU40: 0 | DV40: 0 | DW40: 0 | DX40: 0 | DY40: 0 | DZ40: 0 | EA40: 0 | EB40: 0 | EC40: 0 | ED40: 0 | EE40: 0 | EF40: 0 | EG40: 0 | EH40: 0 | EI40: 0 | EJ40: 0 | EK40: 0 | EL40: 0 | EM40: 0 | EN40: 0 | EO40: 0 | EP40: 0 | EQ40: 0 | ER40: 0 | ES40: 0 | ET40: 0 | EU40: 0 | EV40: 0 | EW40: 0 | EX40: 0 | EY40: 0
D41: Budget Vs Actual | E41: =E40/E37 -> #DIV/0! | F41: =F40/F37 -> #DIV/0! | G41: =G40/G37 -> #DIV/0! | H41: =H40/H37 -> #DIV/0! | I41: =I40/I37 -> #DIV/0! | J41: =J40/J37 -> #DIV/0! | K41: =K40/K37 -> #DIV/0! | L41: =L40/L37 -> #DIV/0! | ... EY41: =EY40/EY37 -> #DIV/0!
D42: Forecast Vs Actual | E42: =E40/E38 -> #DIV/0! | F42: =F40/F38 -> #DIV/0! | G42: =G40/G38 -> #DIV/0! | H42: =H40/H38 -> #DIV/0! | I42: =I40/I38 -> #DIV/0! | J42: =J40/J38 -> #DIV/0! | K42: =K40/K38 -> #DIV/0! | L42: =L40/L38 -> #DIV/0! | ... EY42: =EY40/EY38 -> #DIV/0!
A44: Just Energy | B44: Just Energy | C44: USA | D44: Budget
D45: Forecast | BX45: 3 | BY45: 15 | BZ45: 15 | CA45: 15 | CB45: 12 | CC45: 10 | CD45: 10 | CE45: 10 | CF45: 10 | CG45: 10 | CH45: 10 | CI45: 10 | CJ45: 12 | CK45: 10 | CL45: 9 | CM45: 9 | CN45: 9 | CO45: 9 | CP45: 9 | CQ45: 9 | CR45: 9 | CS45: 9 | CT45: 0 | CU45: 0 | CV45: 0 | CW45: 0 | CX45: 0 | CY45: 0 | CZ45: 0 | DA45: 0 | DB45: 0 | DC45: 0 | DD45: 0 | DE45: 0 | DF45: 0 | DG45: 0 | DH45: 0 | DI45: 0 | DJ45: 0 | DK45: 0 | DL45: 0 | DM45: 0 | DN45: 0 | DO45: 0 | DP45: 0 | DQ45: 0 | DR45: 0 | DS45: 0 | DT45: 0 | DU45: 0 | DV45: 0 | DW45: 0 | DX45: 0 | DY45: 0 | DZ45: 0 | EA45: 0 | EB45: 0 | EC45: 0 | ED45: 0 | EE45: 0 | EF45: 0 | EG45: 0 | EH45: 0 | EI45: 0 | EJ45: 0 | EK45: 0 | EL45: 0 | EM45: 0 | EN45: 0 | EO45: 0 | EP45: 0 | EQ45: 0 | ER45: 0 | ES45: 0 | ET45: 0 | EU45: 0 | EV45: 0 | EW45: 0 | EX45: 0 | EY45: 0
D46: Required | BX46: 3.86 | BY46: 10 | BZ46: 10 | CA46: 9 | CB46: 15 | CC46: 11.86 | CD46: 10.86 | CE46: 12 | CF46: 12 | CG46: 12 | CH46: 12 | CI46: 10 | CJ46: 8 | CK46: 10 | CL46: 9 | CM46: 9 | CN46: 9 | CO46: 9 | CP46: 9 | CQ46: 9 | CR46: 9 | CS46: 9 | CT46: 0 | CU46: 0 | CV46: 0 | CW46: 0 | CX46: 0 | CY46: 0 | CZ46: 0 | DA46: 0 | DB46: 0 | DC46: 0 | DD46: 0 | DE46: 0 | DF46: 0 | DG46: 0 | DH46: 0 | DI46: 0 | DJ46: 0 | DK46: 0 | DL46: 0 | DM46: 0 | DN46: 0 | DO46: 0 | DP46: 0 | DQ46: 0 | DR46: 0 | DS46: 0 | DT46: 0 | DU46: 0 | DV46: 0 | DW46: 0 | DX46: 0 | DY46: 0 | DZ46: 0 | EA46: 0 | EB46: 0 | EC46: 0 | ED46: 0 | EE46: 0 | EF46: 0 | EG46: 0 | EH46: 0 | EI46: 0 | EJ46: 0 | EK46: 0 | EL46: 0 | EM46: 0 | EN46: 0 | EO46: 0 | EP46: 0 | EQ46: 0 | ER46: 0 | ES46: 0 | ET46: 0 | EU46: 0 | EV46: 0 | EW46: 0 | EX46: 0 | EY46: 0
...

Sheet CO
A1: H2R Department | B1: Client Name | C1: Country | E1: 45340 | F1: =E1+7 -> 45347 | G1: =F1+7 -> 45354 | H1: =G1+7 -> 45361 | I1: =H1+7 -> 45368 | J1: =I1+7 -> 45375 | K1: =J1+7 -> 45382 | L1: =K1+7 -> 45389 | M1: =L1+7 -> 45396 | ... EY1: =EX1+7 -> 46390
A2: Door Dash | B2: DoorDash Montreal | C2: Canada | D2: Budget | Q2: 21 | R2: 28 | S2: 28 | T2: 28 | U2: 28 | V2: 28 | W2: 28 | X2: 28 | Y2: 28 | Z2: 28 | AA2: 28 | AB2: 28 | AC2: 28 | AD2: 28 | AE2: 28 | AF2: 28 | AG2: 28 | AH2: 28 | AI2: 28 | AJ2: 28 | AK2: 28 | AL2: 28 | AM2: 28 | AN2: 28 | AO2: 28 | AP2: 28 | AQ2: 28 | AR2: 28 | AS2: 28 | AT2: 28 | AU2: =AT2 -> 28 | AV2: =AU2 -> 28 | AW2: 28
D3: Forecast | P3: 0 | Q3: 22 | R3: 22 | S3: 22 | T3: 11 | U3: 21 | V3: 21 | W3: 17 | X3: 28 | Y3: 24 | Z3: 27 | AA3: 27 | AB3: 27 | AC3: 25 | AD3: 27 | AE3: 19 | AF3: 11 | AG3: 19 | AH3: 17 | AI3: 17 | AJ3: 27 | AK3: 27 | AL3: 27 | AM3: 27 | AN3: 27 | AO3: 30 | AP3: 30 | AQ3: 27 | AR3: 27 | AS3: 31 | AT3: 27 | AU3: 27 | AV3: 27 | AW3: 30 | AX3: 31 | AY3: 27 | AZ3: 27 | BA3: 27 | BB3: 27 | BC3: 27 | BD3: 27 | BE3: 27 | BF3: 27 | BG3: 27 | BH3: 27 | BI3: 27 | BJ3: 28 | BK3: 28 | BL3: 28 | BM3: 27 | BN3: 28 | BO3: 27 | BP3: 25 | BQ3: 25 | BR3: 24 | BS3: 23 | BT3: 23 | BU3: 23 | BV3: 22 | BW3: 22 | BX3: 9
D4: Required | P4: 19.55 | Q4: 18.7 | R4: 18.513 | S4: 20.196 | T4: 10.098 | U4: 20.0376 | V4: 29.6208 | W4: 16 | X4: 25 | Y4: 24 | Z4: 24 | AA4: 24 | AB4: 22 | AC4: 19 | AD4: 28 | AE4: 12 | AF4: 21 | AG4: 21 | AH4: 17 | AI4: 16 | AJ4: 23 | AK4: 22 | AL4: 22 | AM4: 21 | AN4: 20 | AO4: 20 | AP4: 20 | AQ4: 20 | AR4: 27 | AS4: 34 | AT4: 34 | AU4: 36 | AV4: 34 | AW4: 34 | AX4: 34 | AY4: 33 | AZ4: 31 | BA4: 30 | BB4: 30 | BC4: 29 | BD4: 27 | BE4: 27 | BF4: 25 | BG4: 29 | BH4: 28 | BI4: 28 | BJ4: 29 | BK4: 30 | BL4: 29 | BM4: 25 | BN4: 26 | BO4: 25 | BP4: 24 | BQ4: 22 | BR4: 21 | BS4: 21 | BT4: 20 | BU4: 18 | BV4: 17 | BW4: 16 | BX4: 14
D5: Projected | AA5: 27 | AB5: 26 | AC5: 22 | AD5: 34 | AE5: 14 | AF5: 25 | AG5: 25 | AH5: 30 | AI5: 29 | AJ5: 29 | AK5: 28 | AL5: 27 | AM5: 26 | AN5: 26 | AO5: 26 | AP5: 26 | AQ5: 25 | AR5: 46 | AS5: 46 | AT5: 44 | AU5: 44 | AV5: 43 | AW5: 42 | AX5: 42 | AY5: 40 | AZ5: 38 | BA5: 37 | BB5: 37 | BC5: 36 | BD5: 34 | BE5: 33 | BF5: 31 | BG5: 31 | BH5: 31 | BI5: 31 | BJ5: 31 | BK5: 33 | BL5: 33 | BM5: 31 | BN5: 30 | BO5: 29 | BP5: 28 | BQ5: 26 | BR5: 25 | BS5: 24 | BT5: 23 | BU5: 21 | BV5: 20 | BW5: 19 | BX5: 17
D6: Budget Vs Actual | E6: =E4/E2 -> #DIV/0! | F6: =F4/F2 -> #DIV/0! | G6: =G4/G2 -> #DIV/0! | H6: =H4/H2 -> #DIV/0! | I6: =I4/I2 -> #DIV/0! | J6: =J4/J2 -> #DIV/0! | K6: =K4/K2 -> #DIV/0! | L6: =L4/L2 -> #DIV/0! | ... EY6: =EY4/EY2 -> #DIV/0!
